INFO 2025-06-02 12:20:25,742 autoreload 846108 130003624698944 Watching for file changes with StatReloader
INFO 2025-06-04 03:49:46,347 autoreload 11 140643776711552 Watching for file changes with StatReloader
INFO 2025-06-04 03:51:38,980 autoreload 11 139667068795776 Watching for file changes with StatReloader
INFO 2025-06-04 03:54:40,373 autoreload 11 140492161502080 Watching for file changes with StatReloader
INFO 2025-06-04 04:03:31,365 basehttp 11 140492004128448 "GET /api/auth/google-auth HTTP/1.0" 301 0
WARNING 2025-06-04 04:03:31,369 log 11 140492004128448 Method Not Allowed: /api/auth/google-auth/
WARNING 2025-06-04 04:03:31,370 basehttp 11 140492004128448 "GET /api/auth/google-auth/ HTTP/1.0" 405 40
WARNING 2025-06-04 04:03:43,917 log 11 140492004128448 Method Not Allowed: /api/auth/login/
WARNING 2025-06-04 04:03:43,918 basehttp 11 140492004128448 "GET /api/auth/login/ HTTP/1.0" 405 40
WARNING 2025-06-04 04:08:12,778 log 11 140492004128448 Method Not Allowed: /api/auth/login/
WARNING 2025-06-04 04:08:12,779 basehttp 11 140492004128448 "GET /api/auth/login/ HTTP/1.0" 405 40
WARNING 2025-06-04 04:11:36,466 log 11 140492004128448 Bad Request: /api/auth/register/
WARNING 2025-06-04 04:11:36,466 basehttp 11 140492004128448 "POST /api/auth/register/ HTTP/1.0" 400 129
ERROR 2025-06-04 04:13:24,857 log 11 140492004128448 Internal Server Error: /api/auth/register/
Traceback (most recent call last):
  File "/usr/local/lib/python3.11/site-packages/django/db/backends/utils.py", line 105, in _execute
    return self.cursor.execute(sql, params)
           ^^^^^^^^^^^^^^^^^^^^^^^^^^^^^^^^
psycopg2.errors.UniqueViolation: duplicate key value violates unique constraint "authentication_userprofile_user_id_key"
DETAIL:  Key (user_id)=(9c8058f3-cbd5-4be1-a84a-5fbfafa779aa) already exists.


The above exception was the direct cause of the following exception:

Traceback (most recent call last):
  File "/usr/local/lib/python3.11/site-packages/django/core/handlers/exception.py", line 55, in inner
    response = get_response(request)
               ^^^^^^^^^^^^^^^^^^^^^
  File "/usr/local/lib/python3.11/site-packages/django/core/handlers/base.py", line 197, in _get_response
    response = wrapped_callback(request, *callback_args, **callback_kwargs)
               ^^^^^^^^^^^^^^^^^^^^^^^^^^^^^^^^^^^^^^^^^^^^^^^^^^^^^^^^^^^^
  File "/usr/local/lib/python3.11/site-packages/django/views/decorators/csrf.py", line 65, in _view_wrapper
    return view_func(request, *args, **kwargs)
           ^^^^^^^^^^^^^^^^^^^^^^^^^^^^^^^^^^^
  File "/usr/local/lib/python3.11/site-packages/django/views/generic/base.py", line 104, in view
    return self.dispatch(request, *args, **kwargs)
           ^^^^^^^^^^^^^^^^^^^^^^^^^^^^^^^^^^^^^^^
  File "/usr/local/lib/python3.11/site-packages/rest_framework/views.py", line 509, in dispatch
    response = self.handle_exception(exc)
               ^^^^^^^^^^^^^^^^^^^^^^^^^^
  File "/usr/local/lib/python3.11/site-packages/rest_framework/views.py", line 469, in handle_exception
    self.raise_uncaught_exception(exc)
  File "/usr/local/lib/python3.11/site-packages/rest_framework/views.py", line 480, in raise_uncaught_exception
    raise exc
  File "/usr/local/lib/python3.11/site-packages/rest_framework/views.py", line 506, in dispatch
    response = handler(request, *args, **kwargs)
               ^^^^^^^^^^^^^^^^^^^^^^^^^^^^^^^^^
  File "/usr/local/lib/python3.11/site-packages/rest_framework/decorators.py", line 50, in handler
    return func(*args, **kwargs)
           ^^^^^^^^^^^^^^^^^^^^^
  File "/app/authentication/views.py", line 56, in register
    user = serializer.save()
           ^^^^^^^^^^^^^^^^^
  File "/usr/local/lib/python3.11/site-packages/rest_framework/serializers.py", line 208, in save
    self.instance = self.create(validated_data)
                    ^^^^^^^^^^^^^^^^^^^^^^^^^^^
  File "/app/authentication/serializers.py", line 51, in create
    UserProfile.objects.create(user=user)
  File "/usr/local/lib/python3.11/site-packages/django/db/models/manager.py", line 87, in manager_method
    return getattr(self.get_queryset(), name)(*args, **kwargs)
           ^^^^^^^^^^^^^^^^^^^^^^^^^^^^^^^^^^^^^^^^^^^^^^^^^^^
  File "/usr/local/lib/python3.11/site-packages/django/db/models/query.py", line 663, in create
    obj.save(force_insert=True, using=self.db)
  File "/usr/local/lib/python3.11/site-packages/django/db/models/base.py", line 902, in save
    self.save_base(
  File "/usr/local/lib/python3.11/site-packages/django/db/models/base.py", line 1008, in save_base
    updated = self._save_table(
              ^^^^^^^^^^^^^^^^^
  File "/usr/local/lib/python3.11/site-packages/django/db/models/base.py", line 1169, in _save_table
    results = self._do_insert(
              ^^^^^^^^^^^^^^^^
  File "/usr/local/lib/python3.11/site-packages/django/db/models/base.py", line 1210, in _do_insert
    return manager._insert(
           ^^^^^^^^^^^^^^^^
  File "/usr/local/lib/python3.11/site-packages/django/db/models/manager.py", line 87, in manager_method
    return getattr(self.get_queryset(), name)(*args, **kwargs)
           ^^^^^^^^^^^^^^^^^^^^^^^^^^^^^^^^^^^^^^^^^^^^^^^^^^^
  File "/usr/local/lib/python3.11/site-packages/django/db/models/query.py", line 1864, in _insert
    return query.get_compiler(using=using).execute_sql(returning_fields)
           ^^^^^^^^^^^^^^^^^^^^^^^^^^^^^^^^^^^^^^^^^^^^^^^^^^^^^^^^^^^^^
  File "/usr/local/lib/python3.11/site-packages/django/db/models/sql/compiler.py", line 1882, in execute_sql
    cursor.execute(sql, params)
  File "/usr/local/lib/python3.11/site-packages/django/db/backends/utils.py", line 122, in execute
    return super().execute(sql, params)
           ^^^^^^^^^^^^^^^^^^^^^^^^^^^^
  File "/usr/local/lib/python3.11/site-packages/django/db/backends/utils.py", line 79, in execute
    return self._execute_with_wrappers(
           ^^^^^^^^^^^^^^^^^^^^^^^^^^^^
  File "/usr/local/lib/python3.11/site-packages/django/db/backends/utils.py", line 92, in _execute_with_wrappers
    return executor(sql, params, many, context)
           ^^^^^^^^^^^^^^^^^^^^^^^^^^^^^^^^^^^^
  File "/usr/local/lib/python3.11/site-packages/django/db/backends/utils.py", line 100, in _execute
    with self.db.wrap_database_errors:
  File "/usr/local/lib/python3.11/site-packages/django/db/utils.py", line 91, in __exit__
    raise dj_exc_value.with_traceback(traceback) from exc_value
  File "/usr/local/lib/python3.11/site-packages/django/db/backends/utils.py", line 105, in _execute
    return self.cursor.execute(sql, params)
           ^^^^^^^^^^^^^^^^^^^^^^^^^^^^^^^^
django.db.utils.IntegrityError: duplicate key value violates unique constraint "authentication_userprofile_user_id_key"
DETAIL:  Key (user_id)=(9c8058f3-cbd5-4be1-a84a-5fbfafa779aa) already exists.

ERROR 2025-06-04 04:13:24,861 basehttp 11 140492004128448 "POST /api/auth/register/ HTTP/1.0" 500 190047
ERROR 2025-06-04 04:14:33,624 log 11 140492004128448 Internal Server Error: /api/auth/register/
Traceback (most recent call last):
  File "/usr/local/lib/python3.11/site-packages/django/db/backends/utils.py", line 105, in _execute
    return self.cursor.execute(sql, params)
           ^^^^^^^^^^^^^^^^^^^^^^^^^^^^^^^^
psycopg2.errors.UniqueViolation: duplicate key value violates unique constraint "authentication_userprofile_user_id_key"
DETAIL:  Key (user_id)=(6071496f-8351-4940-ade6-09860d97c238) already exists.


The above exception was the direct cause of the following exception:

Traceback (most recent call last):
  File "/usr/local/lib/python3.11/site-packages/django/core/handlers/exception.py", line 55, in inner
    response = get_response(request)
               ^^^^^^^^^^^^^^^^^^^^^
  File "/usr/local/lib/python3.11/site-packages/django/core/handlers/base.py", line 197, in _get_response
    response = wrapped_callback(request, *callback_args, **callback_kwargs)
               ^^^^^^^^^^^^^^^^^^^^^^^^^^^^^^^^^^^^^^^^^^^^^^^^^^^^^^^^^^^^
  File "/usr/local/lib/python3.11/site-packages/django/views/decorators/csrf.py", line 65, in _view_wrapper
    return view_func(request, *args, **kwargs)
           ^^^^^^^^^^^^^^^^^^^^^^^^^^^^^^^^^^^
  File "/usr/local/lib/python3.11/site-packages/django/views/generic/base.py", line 104, in view
    return self.dispatch(request, *args, **kwargs)
           ^^^^^^^^^^^^^^^^^^^^^^^^^^^^^^^^^^^^^^^
  File "/usr/local/lib/python3.11/site-packages/rest_framework/views.py", line 509, in dispatch
    response = self.handle_exception(exc)
               ^^^^^^^^^^^^^^^^^^^^^^^^^^
  File "/usr/local/lib/python3.11/site-packages/rest_framework/views.py", line 469, in handle_exception
    self.raise_uncaught_exception(exc)
  File "/usr/local/lib/python3.11/site-packages/rest_framework/views.py", line 480, in raise_uncaught_exception
    raise exc
  File "/usr/local/lib/python3.11/site-packages/rest_framework/views.py", line 506, in dispatch
    response = handler(request, *args, **kwargs)
               ^^^^^^^^^^^^^^^^^^^^^^^^^^^^^^^^^
  File "/usr/local/lib/python3.11/site-packages/rest_framework/decorators.py", line 50, in handler
    return func(*args, **kwargs)
           ^^^^^^^^^^^^^^^^^^^^^
  File "/app/authentication/views.py", line 56, in register
    user = serializer.save()
           ^^^^^^^^^^^^^^^^^
  File "/usr/local/lib/python3.11/site-packages/rest_framework/serializers.py", line 208, in save
    self.instance = self.create(validated_data)
                    ^^^^^^^^^^^^^^^^^^^^^^^^^^^
  File "/app/authentication/serializers.py", line 51, in create
    UserProfile.objects.create(user=user)
  File "/usr/local/lib/python3.11/site-packages/django/db/models/manager.py", line 87, in manager_method
    return getattr(self.get_queryset(), name)(*args, **kwargs)
           ^^^^^^^^^^^^^^^^^^^^^^^^^^^^^^^^^^^^^^^^^^^^^^^^^^^
  File "/usr/local/lib/python3.11/site-packages/django/db/models/query.py", line 663, in create
    obj.save(force_insert=True, using=self.db)
  File "/usr/local/lib/python3.11/site-packages/django/db/models/base.py", line 902, in save
    self.save_base(
  File "/usr/local/lib/python3.11/site-packages/django/db/models/base.py", line 1008, in save_base
    updated = self._save_table(
              ^^^^^^^^^^^^^^^^^
  File "/usr/local/lib/python3.11/site-packages/django/db/models/base.py", line 1169, in _save_table
    results = self._do_insert(
              ^^^^^^^^^^^^^^^^
  File "/usr/local/lib/python3.11/site-packages/django/db/models/base.py", line 1210, in _do_insert
    return manager._insert(
           ^^^^^^^^^^^^^^^^
  File "/usr/local/lib/python3.11/site-packages/django/db/models/manager.py", line 87, in manager_method
    return getattr(self.get_queryset(), name)(*args, **kwargs)
           ^^^^^^^^^^^^^^^^^^^^^^^^^^^^^^^^^^^^^^^^^^^^^^^^^^^
  File "/usr/local/lib/python3.11/site-packages/django/db/models/query.py", line 1864, in _insert
    return query.get_compiler(using=using).execute_sql(returning_fields)
           ^^^^^^^^^^^^^^^^^^^^^^^^^^^^^^^^^^^^^^^^^^^^^^^^^^^^^^^^^^^^^
  File "/usr/local/lib/python3.11/site-packages/django/db/models/sql/compiler.py", line 1882, in execute_sql
    cursor.execute(sql, params)
  File "/usr/local/lib/python3.11/site-packages/django/db/backends/utils.py", line 122, in execute
    return super().execute(sql, params)
           ^^^^^^^^^^^^^^^^^^^^^^^^^^^^
  File "/usr/local/lib/python3.11/site-packages/django/db/backends/utils.py", line 79, in execute
    return self._execute_with_wrappers(
           ^^^^^^^^^^^^^^^^^^^^^^^^^^^^
  File "/usr/local/lib/python3.11/site-packages/django/db/backends/utils.py", line 92, in _execute_with_wrappers
    return executor(sql, params, many, context)
           ^^^^^^^^^^^^^^^^^^^^^^^^^^^^^^^^^^^^
  File "/usr/local/lib/python3.11/site-packages/django/db/backends/utils.py", line 100, in _execute
    with self.db.wrap_database_errors:
  File "/usr/local/lib/python3.11/site-packages/django/db/utils.py", line 91, in __exit__
    raise dj_exc_value.with_traceback(traceback) from exc_value
  File "/usr/local/lib/python3.11/site-packages/django/db/backends/utils.py", line 105, in _execute
    return self.cursor.execute(sql, params)
           ^^^^^^^^^^^^^^^^^^^^^^^^^^^^^^^^
django.db.utils.IntegrityError: duplicate key value violates unique constraint "authentication_userprofile_user_id_key"
DETAIL:  Key (user_id)=(6071496f-8351-4940-ade6-09860d97c238) already exists.

ERROR 2025-06-04 04:14:33,626 basehttp 11 140492004128448 "POST /api/auth/register/ HTTP/1.0" 500 190062
INFO 2025-06-04 04:18:31,940 autoreload 11 140307725712256 Watching for file changes with StatReloader
ERROR 2025-06-04 04:20:35,380 log 11 140307643492032 Internal Server Error: /api/auth/register/
Traceback (most recent call last):
  File "/usr/local/lib/python3.11/site-packages/django/db/backends/utils.py", line 105, in _execute
    return self.cursor.execute(sql, params)
           ^^^^^^^^^^^^^^^^^^^^^^^^^^^^^^^^
psycopg2.errors.UniqueViolation: duplicate key value violates unique constraint "authentication_userprofile_user_id_key"
DETAIL:  Key (user_id)=(2df45b91-5448-41a2-950e-2ac598127d3f) already exists.


The above exception was the direct cause of the following exception:

Traceback (most recent call last):
  File "/usr/local/lib/python3.11/site-packages/django/core/handlers/exception.py", line 55, in inner
    response = get_response(request)
               ^^^^^^^^^^^^^^^^^^^^^
  File "/usr/local/lib/python3.11/site-packages/django/core/handlers/base.py", line 197, in _get_response
    response = wrapped_callback(request, *callback_args, **callback_kwargs)
               ^^^^^^^^^^^^^^^^^^^^^^^^^^^^^^^^^^^^^^^^^^^^^^^^^^^^^^^^^^^^
  File "/usr/local/lib/python3.11/site-packages/django/views/decorators/csrf.py", line 65, in _view_wrapper
    return view_func(request, *args, **kwargs)
           ^^^^^^^^^^^^^^^^^^^^^^^^^^^^^^^^^^^
  File "/usr/local/lib/python3.11/site-packages/django/views/generic/base.py", line 104, in view
    return self.dispatch(request, *args, **kwargs)
           ^^^^^^^^^^^^^^^^^^^^^^^^^^^^^^^^^^^^^^^
  File "/usr/local/lib/python3.11/site-packages/rest_framework/views.py", line 509, in dispatch
    response = self.handle_exception(exc)
               ^^^^^^^^^^^^^^^^^^^^^^^^^^
  File "/usr/local/lib/python3.11/site-packages/rest_framework/views.py", line 469, in handle_exception
    self.raise_uncaught_exception(exc)
  File "/usr/local/lib/python3.11/site-packages/rest_framework/views.py", line 480, in raise_uncaught_exception
    raise exc
  File "/usr/local/lib/python3.11/site-packages/rest_framework/views.py", line 506, in dispatch
    response = handler(request, *args, **kwargs)
               ^^^^^^^^^^^^^^^^^^^^^^^^^^^^^^^^^
  File "/usr/local/lib/python3.11/site-packages/rest_framework/decorators.py", line 50, in handler
    return func(*args, **kwargs)
           ^^^^^^^^^^^^^^^^^^^^^
  File "/app/authentication/views.py", line 56, in register
    user = serializer.save()
           ^^^^^^^^^^^^^^^^^
  File "/usr/local/lib/python3.11/site-packages/rest_framework/serializers.py", line 208, in save
    self.instance = self.create(validated_data)
                    ^^^^^^^^^^^^^^^^^^^^^^^^^^^
  File "/app/authentication/serializers.py", line 51, in create
    UserProfile.objects.create(user=user)
  File "/usr/local/lib/python3.11/site-packages/django/db/models/manager.py", line 87, in manager_method
    return getattr(self.get_queryset(), name)(*args, **kwargs)
           ^^^^^^^^^^^^^^^^^^^^^^^^^^^^^^^^^^^^^^^^^^^^^^^^^^^
  File "/usr/local/lib/python3.11/site-packages/django/db/models/query.py", line 663, in create
    obj.save(force_insert=True, using=self.db)
  File "/usr/local/lib/python3.11/site-packages/django/db/models/base.py", line 902, in save
    self.save_base(
  File "/usr/local/lib/python3.11/site-packages/django/db/models/base.py", line 1008, in save_base
    updated = self._save_table(
              ^^^^^^^^^^^^^^^^^
  File "/usr/local/lib/python3.11/site-packages/django/db/models/base.py", line 1169, in _save_table
    results = self._do_insert(
              ^^^^^^^^^^^^^^^^
  File "/usr/local/lib/python3.11/site-packages/django/db/models/base.py", line 1210, in _do_insert
    return manager._insert(
           ^^^^^^^^^^^^^^^^
  File "/usr/local/lib/python3.11/site-packages/django/db/models/manager.py", line 87, in manager_method
    return getattr(self.get_queryset(), name)(*args, **kwargs)
           ^^^^^^^^^^^^^^^^^^^^^^^^^^^^^^^^^^^^^^^^^^^^^^^^^^^
  File "/usr/local/lib/python3.11/site-packages/django/db/models/query.py", line 1864, in _insert
    return query.get_compiler(using=using).execute_sql(returning_fields)
           ^^^^^^^^^^^^^^^^^^^^^^^^^^^^^^^^^^^^^^^^^^^^^^^^^^^^^^^^^^^^^
  File "/usr/local/lib/python3.11/site-packages/django/db/models/sql/compiler.py", line 1882, in execute_sql
    cursor.execute(sql, params)
  File "/usr/local/lib/python3.11/site-packages/django/db/backends/utils.py", line 122, in execute
    return super().execute(sql, params)
           ^^^^^^^^^^^^^^^^^^^^^^^^^^^^
  File "/usr/local/lib/python3.11/site-packages/django/db/backends/utils.py", line 79, in execute
    return self._execute_with_wrappers(
           ^^^^^^^^^^^^^^^^^^^^^^^^^^^^
  File "/usr/local/lib/python3.11/site-packages/django/db/backends/utils.py", line 92, in _execute_with_wrappers
    return executor(sql, params, many, context)
           ^^^^^^^^^^^^^^^^^^^^^^^^^^^^^^^^^^^^
  File "/usr/local/lib/python3.11/site-packages/django/db/backends/utils.py", line 100, in _execute
    with self.db.wrap_database_errors:
  File "/usr/local/lib/python3.11/site-packages/django/db/utils.py", line 91, in __exit__
    raise dj_exc_value.with_traceback(traceback) from exc_value
  File "/usr/local/lib/python3.11/site-packages/django/db/backends/utils.py", line 105, in _execute
    return self.cursor.execute(sql, params)
           ^^^^^^^^^^^^^^^^^^^^^^^^^^^^^^^^
django.db.utils.IntegrityError: duplicate key value violates unique constraint "authentication_userprofile_user_id_key"
DETAIL:  Key (user_id)=(2df45b91-5448-41a2-950e-2ac598127d3f) already exists.

ERROR 2025-06-04 04:20:35,384 basehttp 11 140307643492032 "POST /api/auth/register/ HTTP/1.0" 500 190047
ERROR 2025-06-04 04:25:59,680 log 11 140307643492032 Internal Server Error: /api/auth/register/
Traceback (most recent call last):
  File "/usr/local/lib/python3.11/site-packages/django/db/backends/utils.py", line 105, in _execute
    return self.cursor.execute(sql, params)
           ^^^^^^^^^^^^^^^^^^^^^^^^^^^^^^^^
psycopg2.errors.UniqueViolation: duplicate key value violates unique constraint "authentication_userprofile_user_id_key"
DETAIL:  Key (user_id)=(eaa23e3c-57d0-4601-a471-1a81847d56ee) already exists.


The above exception was the direct cause of the following exception:

Traceback (most recent call last):
  File "/usr/local/lib/python3.11/site-packages/django/core/handlers/exception.py", line 55, in inner
    response = get_response(request)
               ^^^^^^^^^^^^^^^^^^^^^
  File "/usr/local/lib/python3.11/site-packages/django/core/handlers/base.py", line 197, in _get_response
    response = wrapped_callback(request, *callback_args, **callback_kwargs)
               ^^^^^^^^^^^^^^^^^^^^^^^^^^^^^^^^^^^^^^^^^^^^^^^^^^^^^^^^^^^^
  File "/usr/local/lib/python3.11/site-packages/django/views/decorators/csrf.py", line 65, in _view_wrapper
    return view_func(request, *args, **kwargs)
           ^^^^^^^^^^^^^^^^^^^^^^^^^^^^^^^^^^^
  File "/usr/local/lib/python3.11/site-packages/django/views/generic/base.py", line 104, in view
    return self.dispatch(request, *args, **kwargs)
           ^^^^^^^^^^^^^^^^^^^^^^^^^^^^^^^^^^^^^^^
  File "/usr/local/lib/python3.11/site-packages/rest_framework/views.py", line 509, in dispatch
    response = self.handle_exception(exc)
               ^^^^^^^^^^^^^^^^^^^^^^^^^^
  File "/usr/local/lib/python3.11/site-packages/rest_framework/views.py", line 469, in handle_exception
    self.raise_uncaught_exception(exc)
  File "/usr/local/lib/python3.11/site-packages/rest_framework/views.py", line 480, in raise_uncaught_exception
    raise exc
  File "/usr/local/lib/python3.11/site-packages/rest_framework/views.py", line 506, in dispatch
    response = handler(request, *args, **kwargs)
               ^^^^^^^^^^^^^^^^^^^^^^^^^^^^^^^^^
  File "/usr/local/lib/python3.11/site-packages/rest_framework/decorators.py", line 50, in handler
    return func(*args, **kwargs)
           ^^^^^^^^^^^^^^^^^^^^^
  File "/app/authentication/views.py", line 56, in register
    user = serializer.save()
           ^^^^^^^^^^^^^^^^^
  File "/usr/local/lib/python3.11/site-packages/rest_framework/serializers.py", line 208, in save
    self.instance = self.create(validated_data)
                    ^^^^^^^^^^^^^^^^^^^^^^^^^^^
  File "/app/authentication/serializers.py", line 51, in create
    UserProfile.objects.create(user=user)
  File "/usr/local/lib/python3.11/site-packages/django/db/models/manager.py", line 87, in manager_method
    return getattr(self.get_queryset(), name)(*args, **kwargs)
           ^^^^^^^^^^^^^^^^^^^^^^^^^^^^^^^^^^^^^^^^^^^^^^^^^^^
  File "/usr/local/lib/python3.11/site-packages/django/db/models/query.py", line 663, in create
    obj.save(force_insert=True, using=self.db)
  File "/usr/local/lib/python3.11/site-packages/django/db/models/base.py", line 902, in save
    self.save_base(
  File "/usr/local/lib/python3.11/site-packages/django/db/models/base.py", line 1008, in save_base
    updated = self._save_table(
              ^^^^^^^^^^^^^^^^^
  File "/usr/local/lib/python3.11/site-packages/django/db/models/base.py", line 1169, in _save_table
    results = self._do_insert(
              ^^^^^^^^^^^^^^^^
  File "/usr/local/lib/python3.11/site-packages/django/db/models/base.py", line 1210, in _do_insert
    return manager._insert(
           ^^^^^^^^^^^^^^^^
  File "/usr/local/lib/python3.11/site-packages/django/db/models/manager.py", line 87, in manager_method
    return getattr(self.get_queryset(), name)(*args, **kwargs)
           ^^^^^^^^^^^^^^^^^^^^^^^^^^^^^^^^^^^^^^^^^^^^^^^^^^^
  File "/usr/local/lib/python3.11/site-packages/django/db/models/query.py", line 1864, in _insert
    return query.get_compiler(using=using).execute_sql(returning_fields)
           ^^^^^^^^^^^^^^^^^^^^^^^^^^^^^^^^^^^^^^^^^^^^^^^^^^^^^^^^^^^^^
  File "/usr/local/lib/python3.11/site-packages/django/db/models/sql/compiler.py", line 1882, in execute_sql
    cursor.execute(sql, params)
  File "/usr/local/lib/python3.11/site-packages/django/db/backends/utils.py", line 122, in execute
    return super().execute(sql, params)
           ^^^^^^^^^^^^^^^^^^^^^^^^^^^^
  File "/usr/local/lib/python3.11/site-packages/django/db/backends/utils.py", line 79, in execute
    return self._execute_with_wrappers(
           ^^^^^^^^^^^^^^^^^^^^^^^^^^^^
  File "/usr/local/lib/python3.11/site-packages/django/db/backends/utils.py", line 92, in _execute_with_wrappers
    return executor(sql, params, many, context)
           ^^^^^^^^^^^^^^^^^^^^^^^^^^^^^^^^^^^^
  File "/usr/local/lib/python3.11/site-packages/django/db/backends/utils.py", line 100, in _execute
    with self.db.wrap_database_errors:
  File "/usr/local/lib/python3.11/site-packages/django/db/utils.py", line 91, in __exit__
    raise dj_exc_value.with_traceback(traceback) from exc_value
  File "/usr/local/lib/python3.11/site-packages/django/db/backends/utils.py", line 105, in _execute
    return self.cursor.execute(sql, params)
           ^^^^^^^^^^^^^^^^^^^^^^^^^^^^^^^^
django.db.utils.IntegrityError: duplicate key value violates unique constraint "authentication_userprofile_user_id_key"
DETAIL:  Key (user_id)=(eaa23e3c-57d0-4601-a471-1a81847d56ee) already exists.

ERROR 2025-06-04 04:25:59,682 basehttp 11 140307643492032 "POST /api/auth/register/ HTTP/1.0" 500 190047
ERROR 2025-06-04 04:28:16,759 log 11 140307643492032 Internal Server Error: /api/auth/register/
Traceback (most recent call last):
  File "/usr/local/lib/python3.11/site-packages/django/db/backends/utils.py", line 105, in _execute
    return self.cursor.execute(sql, params)
           ^^^^^^^^^^^^^^^^^^^^^^^^^^^^^^^^
psycopg2.errors.UniqueViolation: duplicate key value violates unique constraint "authentication_userprofile_user_id_key"
DETAIL:  Key (user_id)=(50dcee5e-7ae3-4f34-9a19-3501216867e0) already exists.


The above exception was the direct cause of the following exception:

Traceback (most recent call last):
  File "/usr/local/lib/python3.11/site-packages/django/core/handlers/exception.py", line 55, in inner
    response = get_response(request)
               ^^^^^^^^^^^^^^^^^^^^^
  File "/usr/local/lib/python3.11/site-packages/django/core/handlers/base.py", line 197, in _get_response
    response = wrapped_callback(request, *callback_args, **callback_kwargs)
               ^^^^^^^^^^^^^^^^^^^^^^^^^^^^^^^^^^^^^^^^^^^^^^^^^^^^^^^^^^^^
  File "/usr/local/lib/python3.11/site-packages/django/views/decorators/csrf.py", line 65, in _view_wrapper
    return view_func(request, *args, **kwargs)
           ^^^^^^^^^^^^^^^^^^^^^^^^^^^^^^^^^^^
  File "/usr/local/lib/python3.11/site-packages/django/views/generic/base.py", line 104, in view
    return self.dispatch(request, *args, **kwargs)
           ^^^^^^^^^^^^^^^^^^^^^^^^^^^^^^^^^^^^^^^
  File "/usr/local/lib/python3.11/site-packages/rest_framework/views.py", line 509, in dispatch
    response = self.handle_exception(exc)
               ^^^^^^^^^^^^^^^^^^^^^^^^^^
  File "/usr/local/lib/python3.11/site-packages/rest_framework/views.py", line 469, in handle_exception
    self.raise_uncaught_exception(exc)
  File "/usr/local/lib/python3.11/site-packages/rest_framework/views.py", line 480, in raise_uncaught_exception
    raise exc
  File "/usr/local/lib/python3.11/site-packages/rest_framework/views.py", line 506, in dispatch
    response = handler(request, *args, **kwargs)
               ^^^^^^^^^^^^^^^^^^^^^^^^^^^^^^^^^
  File "/usr/local/lib/python3.11/site-packages/rest_framework/decorators.py", line 50, in handler
    return func(*args, **kwargs)
           ^^^^^^^^^^^^^^^^^^^^^
  File "/app/authentication/views.py", line 56, in register
    user = serializer.save()
           ^^^^^^^^^^^^^^^^^
  File "/usr/local/lib/python3.11/site-packages/rest_framework/serializers.py", line 208, in save
    self.instance = self.create(validated_data)
                    ^^^^^^^^^^^^^^^^^^^^^^^^^^^
  File "/app/authentication/serializers.py", line 51, in create
    UserProfile.objects.create(user=user)
  File "/usr/local/lib/python3.11/site-packages/django/db/models/manager.py", line 87, in manager_method
    return getattr(self.get_queryset(), name)(*args, **kwargs)
           ^^^^^^^^^^^^^^^^^^^^^^^^^^^^^^^^^^^^^^^^^^^^^^^^^^^
  File "/usr/local/lib/python3.11/site-packages/django/db/models/query.py", line 663, in create
    obj.save(force_insert=True, using=self.db)
  File "/usr/local/lib/python3.11/site-packages/django/db/models/base.py", line 902, in save
    self.save_base(
  File "/usr/local/lib/python3.11/site-packages/django/db/models/base.py", line 1008, in save_base
    updated = self._save_table(
              ^^^^^^^^^^^^^^^^^
  File "/usr/local/lib/python3.11/site-packages/django/db/models/base.py", line 1169, in _save_table
    results = self._do_insert(
              ^^^^^^^^^^^^^^^^
  File "/usr/local/lib/python3.11/site-packages/django/db/models/base.py", line 1210, in _do_insert
    return manager._insert(
           ^^^^^^^^^^^^^^^^
  File "/usr/local/lib/python3.11/site-packages/django/db/models/manager.py", line 87, in manager_method
    return getattr(self.get_queryset(), name)(*args, **kwargs)
           ^^^^^^^^^^^^^^^^^^^^^^^^^^^^^^^^^^^^^^^^^^^^^^^^^^^
  File "/usr/local/lib/python3.11/site-packages/django/db/models/query.py", line 1864, in _insert
    return query.get_compiler(using=using).execute_sql(returning_fields)
           ^^^^^^^^^^^^^^^^^^^^^^^^^^^^^^^^^^^^^^^^^^^^^^^^^^^^^^^^^^^^^
  File "/usr/local/lib/python3.11/site-packages/django/db/models/sql/compiler.py", line 1882, in execute_sql
    cursor.execute(sql, params)
  File "/usr/local/lib/python3.11/site-packages/django/db/backends/utils.py", line 122, in execute
    return super().execute(sql, params)
           ^^^^^^^^^^^^^^^^^^^^^^^^^^^^
  File "/usr/local/lib/python3.11/site-packages/django/db/backends/utils.py", line 79, in execute
    return self._execute_with_wrappers(
           ^^^^^^^^^^^^^^^^^^^^^^^^^^^^
  File "/usr/local/lib/python3.11/site-packages/django/db/backends/utils.py", line 92, in _execute_with_wrappers
    return executor(sql, params, many, context)
           ^^^^^^^^^^^^^^^^^^^^^^^^^^^^^^^^^^^^
  File "/usr/local/lib/python3.11/site-packages/django/db/backends/utils.py", line 100, in _execute
    with self.db.wrap_database_errors:
  File "/usr/local/lib/python3.11/site-packages/django/db/utils.py", line 91, in __exit__
    raise dj_exc_value.with_traceback(traceback) from exc_value
  File "/usr/local/lib/python3.11/site-packages/django/db/backends/utils.py", line 105, in _execute
    return self.cursor.execute(sql, params)
           ^^^^^^^^^^^^^^^^^^^^^^^^^^^^^^^^
django.db.utils.IntegrityError: duplicate key value violates unique constraint "authentication_userprofile_user_id_key"
DETAIL:  Key (user_id)=(50dcee5e-7ae3-4f34-9a19-3501216867e0) already exists.

ERROR 2025-06-04 04:28:16,762 basehttp 11 140307643492032 "POST /api/auth/register/ HTTP/1.0" 500 190071
INFO 2025-06-04 04:34:27,977 autoreload 11 140307725712256 /app/authentication/serializers.py changed, reloading.
INFO 2025-06-04 04:34:28,697 autoreload 34 140444306774912 Watching for file changes with StatReloader
INFO 2025-06-04 04:34:44,132 autoreload 34 140444306774912 /app/authentication/serializers.py changed, reloading.
INFO 2025-06-04 04:34:44,924 autoreload 36 140237036936064 Watching for file changes with StatReloader
INFO 2025-06-04 04:35:09,327 autoreload 11 140139789958016 Watching for file changes with StatReloader
ERROR 2025-06-04 04:35:17,139 log 11 140139707754176 Internal Server Error: /api/auth/register/
Traceback (most recent call last):
  File "/usr/local/lib/python3.11/site-packages/django/core/handlers/exception.py", line 55, in inner
    response = get_response(request)
               ^^^^^^^^^^^^^^^^^^^^^
  File "/usr/local/lib/python3.11/site-packages/django/core/handlers/base.py", line 197, in _get_response
    response = wrapped_callback(request, *callback_args, **callback_kwargs)
               ^^^^^^^^^^^^^^^^^^^^^^^^^^^^^^^^^^^^^^^^^^^^^^^^^^^^^^^^^^^^
  File "/usr/local/lib/python3.11/site-packages/django/views/decorators/csrf.py", line 65, in _view_wrapper
    return view_func(request, *args, **kwargs)
           ^^^^^^^^^^^^^^^^^^^^^^^^^^^^^^^^^^^
  File "/usr/local/lib/python3.11/site-packages/django/views/generic/base.py", line 104, in view
    return self.dispatch(request, *args, **kwargs)
           ^^^^^^^^^^^^^^^^^^^^^^^^^^^^^^^^^^^^^^^
  File "/usr/local/lib/python3.11/site-packages/rest_framework/views.py", line 509, in dispatch
    response = self.handle_exception(exc)
               ^^^^^^^^^^^^^^^^^^^^^^^^^^
  File "/usr/local/lib/python3.11/site-packages/rest_framework/views.py", line 469, in handle_exception
    self.raise_uncaught_exception(exc)
  File "/usr/local/lib/python3.11/site-packages/rest_framework/views.py", line 480, in raise_uncaught_exception
    raise exc
  File "/usr/local/lib/python3.11/site-packages/rest_framework/views.py", line 506, in dispatch
    response = handler(request, *args, **kwargs)
               ^^^^^^^^^^^^^^^^^^^^^^^^^^^^^^^^^
  File "/usr/local/lib/python3.11/site-packages/rest_framework/decorators.py", line 50, in handler
    return func(*args, **kwargs)
           ^^^^^^^^^^^^^^^^^^^^^
  File "/app/authentication/views.py", line 59, in register
    send_verification_email(user)
  File "/app/authentication/views.py", line 387, in send_verification_email
    send_mail(
  File "/usr/local/lib/python3.11/site-packages/django/core/mail/__init__.py", line 92, in send_mail
    return mail.send()
           ^^^^^^^^^^^
  File "/usr/local/lib/python3.11/site-packages/django/core/mail/message.py", line 307, in send
    return self.get_connection(fail_silently).send_messages([self])
           ^^^^^^^^^^^^^^^^^^^^^^^^^^^^^^^^^^^^^^^^^^^^^^^^^^^^^^^^
  File "/usr/local/lib/python3.11/site-packages/django/core/mail/backends/smtp.py", line 128, in send_messages
    new_conn_created = self.open()
                       ^^^^^^^^^^^
  File "/usr/local/lib/python3.11/site-packages/django/core/mail/backends/smtp.py", line 95, in open
    self.connection.login(self.username, self.password)
  File "/usr/local/lib/python3.11/smtplib.py", line 750, in login
    raise last_exception
  File "/usr/local/lib/python3.11/smtplib.py", line 739, in login
    (code, resp) = self.auth(
                   ^^^^^^^^^^
  File "/usr/local/lib/python3.11/smtplib.py", line 662, in auth
    raise SMTPAuthenticationError(code, resp)
smtplib.SMTPAuthenticationError: (535, b'5.7.8 Username and Password not accepted. For more information, go to\n5.7.8  https://support.google.com/mail/?p=BadCredentials d9443c01a7336-23506be23c1sm95313335ad.78 - gsmtp')
ERROR 2025-06-04 04:35:17,142 basehttp 11 140139707754176 "POST /api/auth/register/ HTTP/1.0" 500 133405
WARNING 2025-06-04 04:36:18,673 log 11 140139707754176 Bad Request: /api/auth/register/
WARNING 2025-06-04 04:36:18,674 basehttp 11 140139707754176 "POST /api/auth/register/ HTTP/1.0" 400 47
WARNING 2025-06-04 04:36:41,099 log 11 140139707754176 Bad Request: /api/auth/register/
WARNING 2025-06-04 04:36:41,099 basehttp 11 140139707754176 "POST /api/auth/register/ HTTP/1.0" 400 47
INFO 2025-06-04 04:39:23,449 autoreload 10 140003482160000 Watching for file changes with StatReloader
WARNING 2025-06-04 04:39:34,484 log 10 140003400214208 Bad Request: /api/auth/register/
WARNING 2025-06-04 04:39:34,484 basehttp 10 140003400214208 "POST /api/auth/register/ HTTP/1.0" 400 107
ERROR 2025-06-04 04:40:06,610 log 10 140003400214208 Internal Server Error: /api/auth/register/
Traceback (most recent call last):
  File "/usr/local/lib/python3.11/site-packages/django/core/handlers/exception.py", line 55, in inner
    response = get_response(request)
               ^^^^^^^^^^^^^^^^^^^^^
  File "/usr/local/lib/python3.11/site-packages/django/core/handlers/base.py", line 197, in _get_response
    response = wrapped_callback(request, *callback_args, **callback_kwargs)
               ^^^^^^^^^^^^^^^^^^^^^^^^^^^^^^^^^^^^^^^^^^^^^^^^^^^^^^^^^^^^
  File "/usr/local/lib/python3.11/site-packages/django/views/decorators/csrf.py", line 65, in _view_wrapper
    return view_func(request, *args, **kwargs)
           ^^^^^^^^^^^^^^^^^^^^^^^^^^^^^^^^^^^
  File "/usr/local/lib/python3.11/site-packages/django/views/generic/base.py", line 104, in view
    return self.dispatch(request, *args, **kwargs)
           ^^^^^^^^^^^^^^^^^^^^^^^^^^^^^^^^^^^^^^^
  File "/usr/local/lib/python3.11/site-packages/rest_framework/views.py", line 509, in dispatch
    response = self.handle_exception(exc)
               ^^^^^^^^^^^^^^^^^^^^^^^^^^
  File "/usr/local/lib/python3.11/site-packages/rest_framework/views.py", line 469, in handle_exception
    self.raise_uncaught_exception(exc)
  File "/usr/local/lib/python3.11/site-packages/rest_framework/views.py", line 480, in raise_uncaught_exception
    raise exc
  File "/usr/local/lib/python3.11/site-packages/rest_framework/views.py", line 506, in dispatch
    response = handler(request, *args, **kwargs)
               ^^^^^^^^^^^^^^^^^^^^^^^^^^^^^^^^^
  File "/usr/local/lib/python3.11/site-packages/rest_framework/decorators.py", line 50, in handler
    return func(*args, **kwargs)
           ^^^^^^^^^^^^^^^^^^^^^
  File "/app/authentication/views.py", line 59, in register
    send_verification_email(user)
  File "/app/authentication/views.py", line 387, in send_verification_email
    send_mail(
  File "/usr/local/lib/python3.11/site-packages/django/core/mail/__init__.py", line 92, in send_mail
    return mail.send()
           ^^^^^^^^^^^
  File "/usr/local/lib/python3.11/site-packages/django/core/mail/message.py", line 307, in send
    return self.get_connection(fail_silently).send_messages([self])
           ^^^^^^^^^^^^^^^^^^^^^^^^^^^^^^^^^^^^^^^^^^^^^^^^^^^^^^^^
  File "/usr/local/lib/python3.11/site-packages/django/core/mail/backends/smtp.py", line 128, in send_messages
    new_conn_created = self.open()
                       ^^^^^^^^^^^
  File "/usr/local/lib/python3.11/site-packages/django/core/mail/backends/smtp.py", line 95, in open
    self.connection.login(self.username, self.password)
  File "/usr/local/lib/python3.11/smtplib.py", line 750, in login
    raise last_exception
  File "/usr/local/lib/python3.11/smtplib.py", line 739, in login
    (code, resp) = self.auth(
                   ^^^^^^^^^^
  File "/usr/local/lib/python3.11/smtplib.py", line 662, in auth
    raise SMTPAuthenticationError(code, resp)
smtplib.SMTPAuthenticationError: (535, b'5.7.8 Username and Password not accepted. For more information, go to\n5.7.8  https://support.google.com/mail/?p=BadCredentials d9443c01a7336-23506cd36acsm95424935ad.144 - gsmtp')
ERROR 2025-06-04 04:40:06,613 basehttp 10 140003400214208 "POST /api/auth/register/ HTTP/1.0" 500 133398
INFO 2025-06-06 08:42:24,709 autoreload 11 140014102453120 Watching for file changes with StatReloader
INFO 2025-06-06 08:58:25,091 autoreload 11 140505043676032 Watching for file changes with StatReloader
INFO 2025-06-06 09:00:02,582 autoreload 11 139630752242560 Watching for file changes with StatReloader
INFO 2025-06-06 10:41:09,535 autoreload 11 140450233555840 Watching for file changes with StatReloader
INFO 2025-06-06 11:26:38,525 autoreload 11 140578602232704 Watching for file changes with StatReloader
INFO 2025-06-06 11:27:21,617 basehttp 11 140578520032960 "OPTIONS /api/auth/login/ HTTP/1.0" 200 0
WARNING 2025-06-06 11:27:21,939 log 11 140578520032960 Unauthorized: /api/auth/login/
WARNING 2025-06-06 11:27:21,939 basehttp 11 140578520032960 "POST /api/auth/login/ HTTP/1.0" 401 51
INFO 2025-06-06 11:27:49,397 basehttp 11 140578520032960 "OPTIONS /api/auth/register/ HTTP/1.0" 200 0
WARNING 2025-06-06 11:27:49,420 log 11 140578520032960 Bad Request: /api/auth/register/
WARNING 2025-06-06 11:27:49,420 basehttp 11 140578520032960 "POST /api/auth/register/ HTTP/1.0" 400 82
ERROR 2025-06-06 11:28:05,917 log 11 140578520032960 Internal Server Error: /api/auth/register/
Traceback (most recent call last):
  File "/usr/local/lib/python3.11/site-packages/django/core/handlers/exception.py", line 55, in inner
    response = get_response(request)
               ^^^^^^^^^^^^^^^^^^^^^
  File "/usr/local/lib/python3.11/site-packages/django/core/handlers/base.py", line 197, in _get_response
    response = wrapped_callback(request, *callback_args, **callback_kwargs)
               ^^^^^^^^^^^^^^^^^^^^^^^^^^^^^^^^^^^^^^^^^^^^^^^^^^^^^^^^^^^^
  File "/usr/local/lib/python3.11/site-packages/django/views/decorators/csrf.py", line 65, in _view_wrapper
    return view_func(request, *args, **kwargs)
           ^^^^^^^^^^^^^^^^^^^^^^^^^^^^^^^^^^^
  File "/usr/local/lib/python3.11/site-packages/django/views/generic/base.py", line 104, in view
    return self.dispatch(request, *args, **kwargs)
           ^^^^^^^^^^^^^^^^^^^^^^^^^^^^^^^^^^^^^^^
  File "/usr/local/lib/python3.11/site-packages/rest_framework/views.py", line 509, in dispatch
    response = self.handle_exception(exc)
               ^^^^^^^^^^^^^^^^^^^^^^^^^^
  File "/usr/local/lib/python3.11/site-packages/rest_framework/views.py", line 469, in handle_exception
    self.raise_uncaught_exception(exc)
  File "/usr/local/lib/python3.11/site-packages/rest_framework/views.py", line 480, in raise_uncaught_exception
    raise exc
  File "/usr/local/lib/python3.11/site-packages/rest_framework/views.py", line 506, in dispatch
    response = handler(request, *args, **kwargs)
               ^^^^^^^^^^^^^^^^^^^^^^^^^^^^^^^^^
  File "/usr/local/lib/python3.11/site-packages/rest_framework/decorators.py", line 50, in handler
    return func(*args, **kwargs)
           ^^^^^^^^^^^^^^^^^^^^^
  File "/app/authentication/views.py", line 59, in register
    send_verification_email(user)
  File "/app/authentication/views.py", line 387, in send_verification_email
    send_mail(
  File "/usr/local/lib/python3.11/site-packages/django/core/mail/__init__.py", line 92, in send_mail
    return mail.send()
           ^^^^^^^^^^^
  File "/usr/local/lib/python3.11/site-packages/django/core/mail/message.py", line 307, in send
    return self.get_connection(fail_silently).send_messages([self])
           ^^^^^^^^^^^^^^^^^^^^^^^^^^^^^^^^^^^^^^^^^^^^^^^^^^^^^^^^
  File "/usr/local/lib/python3.11/site-packages/django/core/mail/backends/smtp.py", line 128, in send_messages
    new_conn_created = self.open()
                       ^^^^^^^^^^^
  File "/usr/local/lib/python3.11/site-packages/django/core/mail/backends/smtp.py", line 95, in open
    self.connection.login(self.username, self.password)
  File "/usr/local/lib/python3.11/smtplib.py", line 750, in login
    raise last_exception
  File "/usr/local/lib/python3.11/smtplib.py", line 739, in login
    (code, resp) = self.auth(
                   ^^^^^^^^^^
  File "/usr/local/lib/python3.11/smtplib.py", line 662, in auth
    raise SMTPAuthenticationError(code, resp)
smtplib.SMTPAuthenticationError: (535, b'5.7.8 Username and Password not accepted. For more information, go to\n5.7.8  https://support.google.com/mail/?p=BadCredentials 98e67ed59e1d1-3134b09067dsm1043030a91.22 - gsmtp')
ERROR 2025-06-06 11:28:05,921 basehttp 11 140578520032960 "POST /api/auth/register/ HTTP/1.0" 500 135209
INFO 2025-06-06 11:43:28,119 autoreload 11 139990790351744 Watching for file changes with StatReloader
WARNING 2025-06-06 11:44:21,771 log 11 139990633805504 Bad Request: /api/auth/register/
WARNING 2025-06-06 11:44:21,772 basehttp 11 139990633805504 "POST /api/auth/register/ HTTP/1.0" 400 47
ERROR 2025-06-06 11:44:38,063 log 11 139990633805504 Internal Server Error: /api/auth/register/
Traceback (most recent call last):
  File "/usr/local/lib/python3.11/site-packages/django/core/handlers/exception.py", line 55, in inner
    response = get_response(request)
               ^^^^^^^^^^^^^^^^^^^^^
  File "/usr/local/lib/python3.11/site-packages/django/core/handlers/base.py", line 197, in _get_response
    response = wrapped_callback(request, *callback_args, **callback_kwargs)
               ^^^^^^^^^^^^^^^^^^^^^^^^^^^^^^^^^^^^^^^^^^^^^^^^^^^^^^^^^^^^
  File "/usr/local/lib/python3.11/site-packages/django/views/decorators/csrf.py", line 65, in _view_wrapper
    return view_func(request, *args, **kwargs)
           ^^^^^^^^^^^^^^^^^^^^^^^^^^^^^^^^^^^
  File "/usr/local/lib/python3.11/site-packages/django/views/generic/base.py", line 104, in view
    return self.dispatch(request, *args, **kwargs)
           ^^^^^^^^^^^^^^^^^^^^^^^^^^^^^^^^^^^^^^^
  File "/usr/local/lib/python3.11/site-packages/rest_framework/views.py", line 509, in dispatch
    response = self.handle_exception(exc)
               ^^^^^^^^^^^^^^^^^^^^^^^^^^
  File "/usr/local/lib/python3.11/site-packages/rest_framework/views.py", line 469, in handle_exception
    self.raise_uncaught_exception(exc)
  File "/usr/local/lib/python3.11/site-packages/rest_framework/views.py", line 480, in raise_uncaught_exception
    raise exc
  File "/usr/local/lib/python3.11/site-packages/rest_framework/views.py", line 506, in dispatch
    response = handler(request, *args, **kwargs)
               ^^^^^^^^^^^^^^^^^^^^^^^^^^^^^^^^^
  File "/usr/local/lib/python3.11/site-packages/rest_framework/decorators.py", line 50, in handler
    return func(*args, **kwargs)
           ^^^^^^^^^^^^^^^^^^^^^
  File "/app/authentication/views.py", line 59, in register
    send_verification_email(user)
  File "/app/authentication/views.py", line 387, in send_verification_email
    send_mail(
  File "/usr/local/lib/python3.11/site-packages/django/core/mail/__init__.py", line 92, in send_mail
    return mail.send()
           ^^^^^^^^^^^
  File "/usr/local/lib/python3.11/site-packages/django/core/mail/message.py", line 307, in send
    return self.get_connection(fail_silently).send_messages([self])
           ^^^^^^^^^^^^^^^^^^^^^^^^^^^^^^^^^^^^^^^^^^^^^^^^^^^^^^^^
  File "/usr/local/lib/python3.11/site-packages/django/core/mail/backends/smtp.py", line 128, in send_messages
    new_conn_created = self.open()
                       ^^^^^^^^^^^
  File "/usr/local/lib/python3.11/site-packages/django/core/mail/backends/smtp.py", line 95, in open
    self.connection.login(self.username, self.password)
  File "/usr/local/lib/python3.11/smtplib.py", line 750, in login
    raise last_exception
  File "/usr/local/lib/python3.11/smtplib.py", line 739, in login
    (code, resp) = self.auth(
                   ^^^^^^^^^^
  File "/usr/local/lib/python3.11/smtplib.py", line 662, in auth
    raise SMTPAuthenticationError(code, resp)
smtplib.SMTPAuthenticationError: (535, b'5.7.8 Username and Password not accepted. For more information, go to\n5.7.8  https://support.google.com/mail/?p=BadCredentials 98e67ed59e1d1-31349fc5361sm1148557a91.24 - gsmtp')
ERROR 2025-06-06 11:44:38,068 basehttp 11 139990633805504 "POST /api/auth/register/ HTTP/1.0" 500 135229
ERROR 2025-06-06 11:45:47,326 log 11 139990633805504 Internal Server Error: /api/auth/register/
Traceback (most recent call last):
  File "/usr/local/lib/python3.11/site-packages/django/core/handlers/exception.py", line 55, in inner
    response = get_response(request)
               ^^^^^^^^^^^^^^^^^^^^^
  File "/usr/local/lib/python3.11/site-packages/django/core/handlers/base.py", line 197, in _get_response
    response = wrapped_callback(request, *callback_args, **callback_kwargs)
               ^^^^^^^^^^^^^^^^^^^^^^^^^^^^^^^^^^^^^^^^^^^^^^^^^^^^^^^^^^^^
  File "/usr/local/lib/python3.11/site-packages/django/views/decorators/csrf.py", line 65, in _view_wrapper
    return view_func(request, *args, **kwargs)
           ^^^^^^^^^^^^^^^^^^^^^^^^^^^^^^^^^^^
  File "/usr/local/lib/python3.11/site-packages/django/views/generic/base.py", line 104, in view
    return self.dispatch(request, *args, **kwargs)
           ^^^^^^^^^^^^^^^^^^^^^^^^^^^^^^^^^^^^^^^
  File "/usr/local/lib/python3.11/site-packages/rest_framework/views.py", line 509, in dispatch
    response = self.handle_exception(exc)
               ^^^^^^^^^^^^^^^^^^^^^^^^^^
  File "/usr/local/lib/python3.11/site-packages/rest_framework/views.py", line 469, in handle_exception
    self.raise_uncaught_exception(exc)
  File "/usr/local/lib/python3.11/site-packages/rest_framework/views.py", line 480, in raise_uncaught_exception
    raise exc
  File "/usr/local/lib/python3.11/site-packages/rest_framework/views.py", line 506, in dispatch
    response = handler(request, *args, **kwargs)
               ^^^^^^^^^^^^^^^^^^^^^^^^^^^^^^^^^
  File "/usr/local/lib/python3.11/site-packages/rest_framework/decorators.py", line 50, in handler
    return func(*args, **kwargs)
           ^^^^^^^^^^^^^^^^^^^^^
  File "/app/authentication/views.py", line 59, in register
    send_verification_email(user)
  File "/app/authentication/views.py", line 387, in send_verification_email
    send_mail(
  File "/usr/local/lib/python3.11/site-packages/django/core/mail/__init__.py", line 92, in send_mail
    return mail.send()
           ^^^^^^^^^^^
  File "/usr/local/lib/python3.11/site-packages/django/core/mail/message.py", line 307, in send
    return self.get_connection(fail_silently).send_messages([self])
           ^^^^^^^^^^^^^^^^^^^^^^^^^^^^^^^^^^^^^^^^^^^^^^^^^^^^^^^^
  File "/usr/local/lib/python3.11/site-packages/django/core/mail/backends/smtp.py", line 128, in send_messages
    new_conn_created = self.open()
                       ^^^^^^^^^^^
  File "/usr/local/lib/python3.11/site-packages/django/core/mail/backends/smtp.py", line 95, in open
    self.connection.login(self.username, self.password)
  File "/usr/local/lib/python3.11/smtplib.py", line 750, in login
    raise last_exception
  File "/usr/local/lib/python3.11/smtplib.py", line 739, in login
    (code, resp) = self.auth(
                   ^^^^^^^^^^
  File "/usr/local/lib/python3.11/smtplib.py", line 662, in auth
    raise SMTPAuthenticationError(code, resp)
smtplib.SMTPAuthenticationError: (535, b'5.7.8 Username and Password not accepted. For more information, go to\n5.7.8  https://support.google.com/mail/?p=BadCredentials 98e67ed59e1d1-31349f32ea9sm1162079a91.14 - gsmtp')
ERROR 2025-06-06 11:45:47,328 basehttp 11 139990633805504 "POST /api/auth/register/ HTTP/1.0" 500 135229
INFO 2025-06-06 11:51:40,076 autoreload 11 139990790351744 /app/config/settings.py changed, reloading.
INFO 2025-06-06 11:51:40,776 autoreload 16 139898047576960 Watching for file changes with StatReloader
INFO 2025-06-06 11:52:36,812 basehttp 16 139897965897408 "POST /api/auth/register/ HTTP/1.0" 201 632
INFO 2025-06-06 11:53:08,115 basehttp 16 139897965897408 "POST /api/auth/login/ HTTP/1.0" 200 601
INFO 2025-06-06 11:53:09,302 basehttp 16 139897965897408 "OPTIONS /api/auth/profile/ HTTP/1.0" 200 0
INFO 2025-06-06 11:53:09,316 basehttp 16 139897965897408 "GET /api/auth/profile/ HTTP/1.0" 200 512
INFO 2025-06-06 11:53:19,846 basehttp 16 139897965897408 "GET /api/auth/profile/ HTTP/1.0" 200 512
INFO 2025-06-06 11:53:20,132 basehttp 16 139897965897408 "GET /api/auth/profile/ HTTP/1.0" 200 512
INFO 2025-06-06 11:53:20,898 basehttp 16 139897965897408 "GET /api/auth/profile/ HTTP/1.0" 200 512
INFO 2025-06-06 11:53:23,679 basehttp 16 139897965897408 "GET /api/auth/profile/ HTTP/1.0" 200 512
INFO 2025-06-06 11:53:29,223 basehttp 16 139897965897408 "GET /api/auth/profile/ HTTP/1.0" 200 512
INFO 2025-06-06 11:53:29,622 basehttp 16 139897965897408 "GET /api/auth/profile/ HTTP/1.0" 200 512
INFO 2025-06-06 12:07:37,635 autoreload 11 140606942083968 Watching for file changes with StatReloader
INFO 2025-06-06 12:07:59,700 basehttp 11 140606859896512 "GET /api/auth/profile/ HTTP/1.0" 200 512
INFO 2025-06-06 12:08:00,595 basehttp 11 140606859896512 "GET /api/auth/profile/ HTTP/1.0" 200 512
INFO 2025-06-06 12:08:13,875 basehttp 11 140606859896512 "GET /api/auth/profile/ HTTP/1.0" 200 512
INFO 2025-06-06 12:08:14,439 basehttp 11 140606859896512 "GET /api/auth/profile/ HTTP/1.0" 200 512
INFO 2025-06-06 12:08:14,625 basehttp 11 140606859896512 "GET /api/auth/profile/ HTTP/1.0" 200 512
INFO 2025-06-06 12:08:43,451 basehttp 11 140606859896512 "GET /api/auth/profile/ HTTP/1.0" 200 512
INFO 2025-06-06 12:08:47,340 basehttp 11 140606859896512 "GET /api/auth/profile/ HTTP/1.0" 200 512
INFO 2025-06-06 12:12:39,476 basehttp 11 140606859896512 "OPTIONS /api/auth/logout/ HTTP/1.0" 200 0
INFO 2025-06-06 12:12:39,492 basehttp 11 140606859896512 "POST /api/auth/logout/ HTTP/1.0" 200 31
WARNING 2025-06-06 12:14:25,116 log 11 140606859896512 Unauthorized: /api/auth/login/
WARNING 2025-06-06 12:14:25,117 basehttp 11 140606859896512 "POST /api/auth/login/ HTTP/1.0" 401 51
INFO 2025-06-06 12:14:46,141 basehttp 11 140606859896512 "POST /api/auth/login/ HTTP/1.0" 200 601
INFO 2025-06-06 13:26:15,402 autoreload 11 139802654116736 Watching for file changes with StatReloader
INFO 2025-06-06 13:29:15,947 basehttp 11 139802572744384 "GET /api/auth/profile/ HTTP/1.0" 200 512
INFO 2025-06-06 13:32:48,317 basehttp 11 139802572744384 "POST /api/auth/logout/ HTTP/1.0" 200 31
ERROR 2025-06-06 13:33:14,239 log 11 139802572744384 Internal Server Error: /api/auth/register/
Traceback (most recent call last):
  File "/usr/local/lib/python3.11/site-packages/django/core/handlers/exception.py", line 55, in inner
    response = get_response(request)
               ^^^^^^^^^^^^^^^^^^^^^
  File "/usr/local/lib/python3.11/site-packages/django/core/handlers/base.py", line 197, in _get_response
    response = wrapped_callback(request, *callback_args, **callback_kwargs)
               ^^^^^^^^^^^^^^^^^^^^^^^^^^^^^^^^^^^^^^^^^^^^^^^^^^^^^^^^^^^^
  File "/usr/local/lib/python3.11/site-packages/django/views/decorators/csrf.py", line 65, in _view_wrapper
    return view_func(request, *args, **kwargs)
           ^^^^^^^^^^^^^^^^^^^^^^^^^^^^^^^^^^^
  File "/usr/local/lib/python3.11/site-packages/django/views/generic/base.py", line 104, in view
    return self.dispatch(request, *args, **kwargs)
           ^^^^^^^^^^^^^^^^^^^^^^^^^^^^^^^^^^^^^^^
  File "/usr/local/lib/python3.11/site-packages/rest_framework/views.py", line 509, in dispatch
    response = self.handle_exception(exc)
               ^^^^^^^^^^^^^^^^^^^^^^^^^^
  File "/usr/local/lib/python3.11/site-packages/rest_framework/views.py", line 469, in handle_exception
    self.raise_uncaught_exception(exc)
  File "/usr/local/lib/python3.11/site-packages/rest_framework/views.py", line 480, in raise_uncaught_exception
    raise exc
  File "/usr/local/lib/python3.11/site-packages/rest_framework/views.py", line 506, in dispatch
    response = handler(request, *args, **kwargs)
               ^^^^^^^^^^^^^^^^^^^^^^^^^^^^^^^^^
  File "/usr/local/lib/python3.11/site-packages/rest_framework/decorators.py", line 50, in handler
    return func(*args, **kwargs)
           ^^^^^^^^^^^^^^^^^^^^^
  File "/app/authentication/views.py", line 59, in register
    send_verification_email(user)
  File "/app/authentication/views.py", line 387, in send_verification_email
    send_mail(
  File "/usr/local/lib/python3.11/site-packages/django/core/mail/__init__.py", line 92, in send_mail
    return mail.send()
           ^^^^^^^^^^^
  File "/usr/local/lib/python3.11/site-packages/django/core/mail/message.py", line 307, in send
    return self.get_connection(fail_silently).send_messages([self])
           ^^^^^^^^^^^^^^^^^^^^^^^^^^^^^^^^^^^^^^^^^^^^^^^^^^^^^^^^
  File "/usr/local/lib/python3.11/site-packages/django/core/mail/backends/smtp.py", line 128, in send_messages
    new_conn_created = self.open()
                       ^^^^^^^^^^^
  File "/usr/local/lib/python3.11/site-packages/django/core/mail/backends/smtp.py", line 95, in open
    self.connection.login(self.username, self.password)
  File "/usr/local/lib/python3.11/smtplib.py", line 750, in login
    raise last_exception
  File "/usr/local/lib/python3.11/smtplib.py", line 739, in login
    (code, resp) = self.auth(
                   ^^^^^^^^^^
  File "/usr/local/lib/python3.11/smtplib.py", line 662, in auth
    raise SMTPAuthenticationError(code, resp)
smtplib.SMTPAuthenticationError: (535, b'5.7.8 Username and Password not accepted. For more information, go to\n5.7.8  https://support.google.com/mail/?p=BadCredentials d2e1a72fcca58-7482b083a9bsm1254069b3a.77 - gsmtp')
ERROR 2025-06-06 13:33:14,242 basehttp 11 139802572744384 "POST /api/auth/register/ HTTP/1.0" 500 135380
ERROR 2025-06-06 13:33:46,985 log 11 139802572744384 Internal Server Error: /api/auth/register/
Traceback (most recent call last):
  File "/usr/local/lib/python3.11/site-packages/django/core/handlers/exception.py", line 55, in inner
    response = get_response(request)
               ^^^^^^^^^^^^^^^^^^^^^
  File "/usr/local/lib/python3.11/site-packages/django/core/handlers/base.py", line 197, in _get_response
    response = wrapped_callback(request, *callback_args, **callback_kwargs)
               ^^^^^^^^^^^^^^^^^^^^^^^^^^^^^^^^^^^^^^^^^^^^^^^^^^^^^^^^^^^^
  File "/usr/local/lib/python3.11/site-packages/django/views/decorators/csrf.py", line 65, in _view_wrapper
    return view_func(request, *args, **kwargs)
           ^^^^^^^^^^^^^^^^^^^^^^^^^^^^^^^^^^^
  File "/usr/local/lib/python3.11/site-packages/django/views/generic/base.py", line 104, in view
    return self.dispatch(request, *args, **kwargs)
           ^^^^^^^^^^^^^^^^^^^^^^^^^^^^^^^^^^^^^^^
  File "/usr/local/lib/python3.11/site-packages/rest_framework/views.py", line 509, in dispatch
    response = self.handle_exception(exc)
               ^^^^^^^^^^^^^^^^^^^^^^^^^^
  File "/usr/local/lib/python3.11/site-packages/rest_framework/views.py", line 469, in handle_exception
    self.raise_uncaught_exception(exc)
  File "/usr/local/lib/python3.11/site-packages/rest_framework/views.py", line 480, in raise_uncaught_exception
    raise exc
  File "/usr/local/lib/python3.11/site-packages/rest_framework/views.py", line 506, in dispatch
    response = handler(request, *args, **kwargs)
               ^^^^^^^^^^^^^^^^^^^^^^^^^^^^^^^^^
  File "/usr/local/lib/python3.11/site-packages/rest_framework/decorators.py", line 50, in handler
    return func(*args, **kwargs)
           ^^^^^^^^^^^^^^^^^^^^^
  File "/app/authentication/views.py", line 59, in register
    send_verification_email(user)
  File "/app/authentication/views.py", line 387, in send_verification_email
    send_mail(
  File "/usr/local/lib/python3.11/site-packages/django/core/mail/__init__.py", line 92, in send_mail
    return mail.send()
           ^^^^^^^^^^^
  File "/usr/local/lib/python3.11/site-packages/django/core/mail/message.py", line 307, in send
    return self.get_connection(fail_silently).send_messages([self])
           ^^^^^^^^^^^^^^^^^^^^^^^^^^^^^^^^^^^^^^^^^^^^^^^^^^^^^^^^
  File "/usr/local/lib/python3.11/site-packages/django/core/mail/backends/smtp.py", line 128, in send_messages
    new_conn_created = self.open()
                       ^^^^^^^^^^^
  File "/usr/local/lib/python3.11/site-packages/django/core/mail/backends/smtp.py", line 95, in open
    self.connection.login(self.username, self.password)
  File "/usr/local/lib/python3.11/smtplib.py", line 750, in login
    raise last_exception
  File "/usr/local/lib/python3.11/smtplib.py", line 739, in login
    (code, resp) = self.auth(
                   ^^^^^^^^^^
  File "/usr/local/lib/python3.11/smtplib.py", line 662, in auth
    raise SMTPAuthenticationError(code, resp)
smtplib.SMTPAuthenticationError: (535, b'5.7.8 Username and Password not accepted. For more information, go to\n5.7.8  https://support.google.com/mail/?p=BadCredentials d2e1a72fcca58-7482b0c7dacsm1289592b3a.141 - gsmtp')
ERROR 2025-06-06 13:33:46,987 basehttp 11 139802572744384 "POST /api/auth/register/ HTTP/1.0" 500 135389
INFO 2025-06-06 13:34:56,649 autoreload 11 140667868593024 Watching for file changes with StatReloader
ERROR 2025-06-06 13:35:02,217 log 11 140667786356416 Internal Server Error: /api/auth/register/
Traceback (most recent call last):
  File "/usr/local/lib/python3.11/site-packages/django/core/handlers/exception.py", line 55, in inner
    response = get_response(request)
               ^^^^^^^^^^^^^^^^^^^^^
  File "/usr/local/lib/python3.11/site-packages/django/core/handlers/base.py", line 197, in _get_response
    response = wrapped_callback(request, *callback_args, **callback_kwargs)
               ^^^^^^^^^^^^^^^^^^^^^^^^^^^^^^^^^^^^^^^^^^^^^^^^^^^^^^^^^^^^
  File "/usr/local/lib/python3.11/site-packages/django/views/decorators/csrf.py", line 65, in _view_wrapper
    return view_func(request, *args, **kwargs)
           ^^^^^^^^^^^^^^^^^^^^^^^^^^^^^^^^^^^
  File "/usr/local/lib/python3.11/site-packages/django/views/generic/base.py", line 104, in view
    return self.dispatch(request, *args, **kwargs)
           ^^^^^^^^^^^^^^^^^^^^^^^^^^^^^^^^^^^^^^^
  File "/usr/local/lib/python3.11/site-packages/rest_framework/views.py", line 509, in dispatch
    response = self.handle_exception(exc)
               ^^^^^^^^^^^^^^^^^^^^^^^^^^
  File "/usr/local/lib/python3.11/site-packages/rest_framework/views.py", line 469, in handle_exception
    self.raise_uncaught_exception(exc)
  File "/usr/local/lib/python3.11/site-packages/rest_framework/views.py", line 480, in raise_uncaught_exception
    raise exc
  File "/usr/local/lib/python3.11/site-packages/rest_framework/views.py", line 506, in dispatch
    response = handler(request, *args, **kwargs)
               ^^^^^^^^^^^^^^^^^^^^^^^^^^^^^^^^^
  File "/usr/local/lib/python3.11/site-packages/rest_framework/decorators.py", line 50, in handler
    return func(*args, **kwargs)
           ^^^^^^^^^^^^^^^^^^^^^
  File "/app/authentication/views.py", line 59, in register
    send_verification_email(user)
  File "/app/authentication/views.py", line 387, in send_verification_email
    send_mail(
  File "/usr/local/lib/python3.11/site-packages/django/core/mail/__init__.py", line 92, in send_mail
    return mail.send()
           ^^^^^^^^^^^
  File "/usr/local/lib/python3.11/site-packages/django/core/mail/message.py", line 307, in send
    return self.get_connection(fail_silently).send_messages([self])
           ^^^^^^^^^^^^^^^^^^^^^^^^^^^^^^^^^^^^^^^^^^^^^^^^^^^^^^^^
  File "/usr/local/lib/python3.11/site-packages/django/core/mail/backends/smtp.py", line 128, in send_messages
    new_conn_created = self.open()
                       ^^^^^^^^^^^
  File "/usr/local/lib/python3.11/site-packages/django/core/mail/backends/smtp.py", line 95, in open
    self.connection.login(self.username, self.password)
  File "/usr/local/lib/python3.11/smtplib.py", line 750, in login
    raise last_exception
  File "/usr/local/lib/python3.11/smtplib.py", line 739, in login
    (code, resp) = self.auth(
                   ^^^^^^^^^^
  File "/usr/local/lib/python3.11/smtplib.py", line 662, in auth
    raise SMTPAuthenticationError(code, resp)
smtplib.SMTPAuthenticationError: (535, b'5.7.8 Username and Password not accepted. For more information, go to\n5.7.8  https://support.google.com/mail/?p=BadCredentials d2e1a72fcca58-7482b0ea3cdsm1255219b3a.159 - gsmtp')
ERROR 2025-06-06 13:35:02,220 basehttp 11 140667786356416 "POST /api/auth/register/ HTTP/1.0" 500 135389
INFO 2025-06-06 13:49:26,601 autoreload 11 140667868593024 /app/config/settings.py changed, reloading.
INFO 2025-06-06 13:49:27,265 autoreload 14 140700425120640 Watching for file changes with StatReloader
ERROR 2025-06-06 13:49:38,189 log 14 140700343592640 Internal Server Error: /api/auth/register/
Traceback (most recent call last):
  File "/usr/local/lib/python3.11/site-packages/django/core/handlers/exception.py", line 55, in inner
    response = get_response(request)
               ^^^^^^^^^^^^^^^^^^^^^
  File "/usr/local/lib/python3.11/site-packages/django/core/handlers/base.py", line 197, in _get_response
    response = wrapped_callback(request, *callback_args, **callback_kwargs)
               ^^^^^^^^^^^^^^^^^^^^^^^^^^^^^^^^^^^^^^^^^^^^^^^^^^^^^^^^^^^^
  File "/usr/local/lib/python3.11/site-packages/django/views/decorators/csrf.py", line 65, in _view_wrapper
    return view_func(request, *args, **kwargs)
           ^^^^^^^^^^^^^^^^^^^^^^^^^^^^^^^^^^^
  File "/usr/local/lib/python3.11/site-packages/django/views/generic/base.py", line 104, in view
    return self.dispatch(request, *args, **kwargs)
           ^^^^^^^^^^^^^^^^^^^^^^^^^^^^^^^^^^^^^^^
  File "/usr/local/lib/python3.11/site-packages/rest_framework/views.py", line 509, in dispatch
    response = self.handle_exception(exc)
               ^^^^^^^^^^^^^^^^^^^^^^^^^^
  File "/usr/local/lib/python3.11/site-packages/rest_framework/views.py", line 469, in handle_exception
    self.raise_uncaught_exception(exc)
  File "/usr/local/lib/python3.11/site-packages/rest_framework/views.py", line 480, in raise_uncaught_exception
    raise exc
  File "/usr/local/lib/python3.11/site-packages/rest_framework/views.py", line 506, in dispatch
    response = handler(request, *args, **kwargs)
               ^^^^^^^^^^^^^^^^^^^^^^^^^^^^^^^^^
  File "/usr/local/lib/python3.11/site-packages/rest_framework/decorators.py", line 50, in handler
    return func(*args, **kwargs)
           ^^^^^^^^^^^^^^^^^^^^^
  File "/app/authentication/views.py", line 59, in register
    send_verification_email(user)
  File "/app/authentication/views.py", line 387, in send_verification_email
    send_mail(
  File "/usr/local/lib/python3.11/site-packages/django/core/mail/__init__.py", line 92, in send_mail
    return mail.send()
           ^^^^^^^^^^^
  File "/usr/local/lib/python3.11/site-packages/django/core/mail/message.py", line 307, in send
    return self.get_connection(fail_silently).send_messages([self])
           ^^^^^^^^^^^^^^^^^^^^^^^^^^^^^^^^^^^^^^^^^^^^^^^^^^^^^^^^
  File "/usr/local/lib/python3.11/site-packages/django/core/mail/backends/smtp.py", line 128, in send_messages
    new_conn_created = self.open()
                       ^^^^^^^^^^^
  File "/usr/local/lib/python3.11/site-packages/django/core/mail/backends/smtp.py", line 95, in open
    self.connection.login(self.username, self.password)
  File "/usr/local/lib/python3.11/smtplib.py", line 750, in login
    raise last_exception
  File "/usr/local/lib/python3.11/smtplib.py", line 739, in login
    (code, resp) = self.auth(
                   ^^^^^^^^^^
  File "/usr/local/lib/python3.11/smtplib.py", line 662, in auth
    raise SMTPAuthenticationError(code, resp)
smtplib.SMTPAuthenticationError: (535, b'5.7.8 Username and Password not accepted. For more information, go to\n5.7.8  https://support.google.com/mail/?p=BadCredentials 98e67ed59e1d1-31349ffaf3bsm1320441a91.46 - gsmtp')
ERROR 2025-06-06 13:49:38,191 basehttp 14 140700343592640 "POST /api/auth/register/ HTTP/1.0" 500 135380
INFO 2025-06-06 13:50:41,256 autoreload 11 140074023709568 Watching for file changes with StatReloader
INFO 2025-06-06 13:51:20,653 autoreload 11 139900846230400 Watching for file changes with StatReloader
ERROR 2025-06-06 13:51:27,933 log 11 139900764546752 Internal Server Error: /api/auth/register/
Traceback (most recent call last):
  File "/usr/local/lib/python3.11/site-packages/django/core/handlers/exception.py", line 55, in inner
    response = get_response(request)
               ^^^^^^^^^^^^^^^^^^^^^
  File "/usr/local/lib/python3.11/site-packages/django/core/handlers/base.py", line 197, in _get_response
    response = wrapped_callback(request, *callback_args, **callback_kwargs)
               ^^^^^^^^^^^^^^^^^^^^^^^^^^^^^^^^^^^^^^^^^^^^^^^^^^^^^^^^^^^^
  File "/usr/local/lib/python3.11/site-packages/django/views/decorators/csrf.py", line 65, in _view_wrapper
    return view_func(request, *args, **kwargs)
           ^^^^^^^^^^^^^^^^^^^^^^^^^^^^^^^^^^^
  File "/usr/local/lib/python3.11/site-packages/django/views/generic/base.py", line 104, in view
    return self.dispatch(request, *args, **kwargs)
           ^^^^^^^^^^^^^^^^^^^^^^^^^^^^^^^^^^^^^^^
  File "/usr/local/lib/python3.11/site-packages/rest_framework/views.py", line 509, in dispatch
    response = self.handle_exception(exc)
               ^^^^^^^^^^^^^^^^^^^^^^^^^^
  File "/usr/local/lib/python3.11/site-packages/rest_framework/views.py", line 469, in handle_exception
    self.raise_uncaught_exception(exc)
  File "/usr/local/lib/python3.11/site-packages/rest_framework/views.py", line 480, in raise_uncaught_exception
    raise exc
  File "/usr/local/lib/python3.11/site-packages/rest_framework/views.py", line 506, in dispatch
    response = handler(request, *args, **kwargs)
               ^^^^^^^^^^^^^^^^^^^^^^^^^^^^^^^^^
  File "/usr/local/lib/python3.11/site-packages/rest_framework/decorators.py", line 50, in handler
    return func(*args, **kwargs)
           ^^^^^^^^^^^^^^^^^^^^^
  File "/app/authentication/views.py", line 59, in register
    send_verification_email(user)
  File "/app/authentication/views.py", line 387, in send_verification_email
    send_mail(
  File "/usr/local/lib/python3.11/site-packages/django/core/mail/__init__.py", line 92, in send_mail
    return mail.send()
           ^^^^^^^^^^^
  File "/usr/local/lib/python3.11/site-packages/django/core/mail/message.py", line 307, in send
    return self.get_connection(fail_silently).send_messages([self])
           ^^^^^^^^^^^^^^^^^^^^^^^^^^^^^^^^^^^^^^^^^^^^^^^^^^^^^^^^
  File "/usr/local/lib/python3.11/site-packages/django/core/mail/backends/smtp.py", line 128, in send_messages
    new_conn_created = self.open()
                       ^^^^^^^^^^^
  File "/usr/local/lib/python3.11/site-packages/django/core/mail/backends/smtp.py", line 95, in open
    self.connection.login(self.username, self.password)
  File "/usr/local/lib/python3.11/smtplib.py", line 750, in login
    raise last_exception
  File "/usr/local/lib/python3.11/smtplib.py", line 739, in login
    (code, resp) = self.auth(
                   ^^^^^^^^^^
  File "/usr/local/lib/python3.11/smtplib.py", line 662, in auth
    raise SMTPAuthenticationError(code, resp)
smtplib.SMTPAuthenticationError: (535, b'5.7.8 Username and Password not accepted. For more information, go to\n5.7.8  https://support.google.com/mail/?p=BadCredentials d9443c01a7336-23603410b57sm12394965ad.209 - gsmtp')
ERROR 2025-06-06 13:51:27,935 basehttp 11 139900764546752 "POST /api/auth/register/ HTTP/1.0" 500 135399
ERROR 2025-06-06 13:52:00,122 log 11 139900764546752 Internal Server Error: /api/auth/register/
Traceback (most recent call last):
  File "/usr/local/lib/python3.11/site-packages/django/core/handlers/exception.py", line 55, in inner
    response = get_response(request)
               ^^^^^^^^^^^^^^^^^^^^^
  File "/usr/local/lib/python3.11/site-packages/django/core/handlers/base.py", line 197, in _get_response
    response = wrapped_callback(request, *callback_args, **callback_kwargs)
               ^^^^^^^^^^^^^^^^^^^^^^^^^^^^^^^^^^^^^^^^^^^^^^^^^^^^^^^^^^^^
  File "/usr/local/lib/python3.11/site-packages/django/views/decorators/csrf.py", line 65, in _view_wrapper
    return view_func(request, *args, **kwargs)
           ^^^^^^^^^^^^^^^^^^^^^^^^^^^^^^^^^^^
  File "/usr/local/lib/python3.11/site-packages/django/views/generic/base.py", line 104, in view
    return self.dispatch(request, *args, **kwargs)
           ^^^^^^^^^^^^^^^^^^^^^^^^^^^^^^^^^^^^^^^
  File "/usr/local/lib/python3.11/site-packages/rest_framework/views.py", line 509, in dispatch
    response = self.handle_exception(exc)
               ^^^^^^^^^^^^^^^^^^^^^^^^^^
  File "/usr/local/lib/python3.11/site-packages/rest_framework/views.py", line 469, in handle_exception
    self.raise_uncaught_exception(exc)
  File "/usr/local/lib/python3.11/site-packages/rest_framework/views.py", line 480, in raise_uncaught_exception
    raise exc
  File "/usr/local/lib/python3.11/site-packages/rest_framework/views.py", line 506, in dispatch
    response = handler(request, *args, **kwargs)
               ^^^^^^^^^^^^^^^^^^^^^^^^^^^^^^^^^
  File "/usr/local/lib/python3.11/site-packages/rest_framework/decorators.py", line 50, in handler
    return func(*args, **kwargs)
           ^^^^^^^^^^^^^^^^^^^^^
  File "/app/authentication/views.py", line 59, in register
    send_verification_email(user)
  File "/app/authentication/views.py", line 387, in send_verification_email
    send_mail(
  File "/usr/local/lib/python3.11/site-packages/django/core/mail/__init__.py", line 92, in send_mail
    return mail.send()
           ^^^^^^^^^^^
  File "/usr/local/lib/python3.11/site-packages/django/core/mail/message.py", line 307, in send
    return self.get_connection(fail_silently).send_messages([self])
           ^^^^^^^^^^^^^^^^^^^^^^^^^^^^^^^^^^^^^^^^^^^^^^^^^^^^^^^^
  File "/usr/local/lib/python3.11/site-packages/django/core/mail/backends/smtp.py", line 128, in send_messages
    new_conn_created = self.open()
                       ^^^^^^^^^^^
  File "/usr/local/lib/python3.11/site-packages/django/core/mail/backends/smtp.py", line 95, in open
    self.connection.login(self.username, self.password)
  File "/usr/local/lib/python3.11/smtplib.py", line 750, in login
    raise last_exception
  File "/usr/local/lib/python3.11/smtplib.py", line 739, in login
    (code, resp) = self.auth(
                   ^^^^^^^^^^
  File "/usr/local/lib/python3.11/smtplib.py", line 662, in auth
    raise SMTPAuthenticationError(code, resp)
smtplib.SMTPAuthenticationError: (535, b'5.7.8 Username and Password not accepted. For more information, go to\n5.7.8  https://support.google.com/mail/?p=BadCredentials d9443c01a7336-23603096949sm12446685ad.67 - gsmtp')
ERROR 2025-06-06 13:52:00,124 basehttp 11 139900764546752 "POST /api/auth/register/ HTTP/1.0" 500 135390
INFO 2025-06-06 13:54:07,444 autoreload 11 140617295100800 Watching for file changes with StatReloader
INFO 2025-06-06 13:54:10,938 basehttp 11 140617213535936 "POST /api/auth/register/ HTTP/1.0" 201 631
INFO 2025-06-06 13:55:32,017 basehttp 11 140617213535936 "POST /api/auth/login/ HTTP/1.0" 200 600
INFO 2025-06-06 14:00:52,330 autoreload 11 140617295100800 /app/config/settings.py changed, reloading.
INFO 2025-06-06 14:00:52,985 autoreload 15 140308959959936 Watching for file changes with StatReloader
INFO 2025-06-06 14:01:53,916 autoreload 15 140308959959936 /app/authentication/serializers.py changed, reloading.
INFO 2025-06-06 14:01:54,823 autoreload 17 139711775529856 Watching for file changes with StatReloader
INFO 2025-06-06 14:02:40,603 autoreload 11 140352516672384 Watching for file changes with StatReloader
INFO 2025-06-06 14:04:59,280 autoreload 11 140183506230144 Watching for file changes with StatReloader
WARNING 2025-06-06 14:05:06,778 log 11 140183424984768 Forbidden: /api/auth/profile/
WARNING 2025-06-06 14:05:06,778 basehttp 11 140183424984768 "GET /api/auth/profile/ HTTP/1.0" 403 27
WARNING 2025-06-06 14:05:06,806 log 11 140183424984768 Forbidden: /api/auth/logout/
WARNING 2025-06-06 14:05:06,807 basehttp 11 140183424984768 "POST /api/auth/logout/ HTTP/1.0" 403 27
INFO 2025-06-06 14:05:31,247 serializers 11 140183424984768 Sending verification email to sanupam2004@gmail.com
INFO 2025-06-06 14:05:31,247 serializers 11 140183424984768 Using email backend: django.core.mail.backends.smtp.EmailBackend
INFO 2025-06-06 14:05:31,248 serializers 11 140183424984768 From email: sanupam2004@gmail.com
ERROR 2025-06-06 14:05:33,657 serializers 11 140183424984768 Failed to send verification email to sanupam2004@gmail.com: (535, b'5.7.8 Username and Password not accepted. For more information, go to\n5.7.8  https://support.google.com/mail/?p=BadCredentials d9443c01a7336-236034056e7sm12596995ad.166 - gsmtp')
ERROR 2025-06-06 14:05:36,199 log 11 140183424984768 Internal Server Error: /api/auth/register/
Traceback (most recent call last):
  File "/usr/local/lib/python3.11/site-packages/django/core/handlers/exception.py", line 55, in inner
    response = get_response(request)
               ^^^^^^^^^^^^^^^^^^^^^
  File "/usr/local/lib/python3.11/site-packages/django/core/handlers/base.py", line 197, in _get_response
    response = wrapped_callback(request, *callback_args, **callback_kwargs)
               ^^^^^^^^^^^^^^^^^^^^^^^^^^^^^^^^^^^^^^^^^^^^^^^^^^^^^^^^^^^^
  File "/usr/local/lib/python3.11/site-packages/django/views/decorators/csrf.py", line 65, in _view_wrapper
    return view_func(request, *args, **kwargs)
           ^^^^^^^^^^^^^^^^^^^^^^^^^^^^^^^^^^^
  File "/usr/local/lib/python3.11/site-packages/django/views/generic/base.py", line 104, in view
    return self.dispatch(request, *args, **kwargs)
           ^^^^^^^^^^^^^^^^^^^^^^^^^^^^^^^^^^^^^^^
  File "/usr/local/lib/python3.11/site-packages/rest_framework/views.py", line 509, in dispatch
    response = self.handle_exception(exc)
               ^^^^^^^^^^^^^^^^^^^^^^^^^^
  File "/usr/local/lib/python3.11/site-packages/rest_framework/views.py", line 469, in handle_exception
    self.raise_uncaught_exception(exc)
  File "/usr/local/lib/python3.11/site-packages/rest_framework/views.py", line 480, in raise_uncaught_exception
    raise exc
  File "/usr/local/lib/python3.11/site-packages/rest_framework/views.py", line 506, in dispatch
    response = handler(request, *args, **kwargs)
               ^^^^^^^^^^^^^^^^^^^^^^^^^^^^^^^^^
  File "/usr/local/lib/python3.11/site-packages/rest_framework/decorators.py", line 50, in handler
    return func(*args, **kwargs)
           ^^^^^^^^^^^^^^^^^^^^^
  File "/app/authentication/views.py", line 59, in register
    send_verification_email(user)
  File "/app/authentication/views.py", line 387, in send_verification_email
    send_mail(
  File "/usr/local/lib/python3.11/site-packages/django/core/mail/__init__.py", line 92, in send_mail
    return mail.send()
           ^^^^^^^^^^^
  File "/usr/local/lib/python3.11/site-packages/django/core/mail/message.py", line 307, in send
    return self.get_connection(fail_silently).send_messages([self])
           ^^^^^^^^^^^^^^^^^^^^^^^^^^^^^^^^^^^^^^^^^^^^^^^^^^^^^^^^
  File "/usr/local/lib/python3.11/site-packages/django/core/mail/backends/smtp.py", line 128, in send_messages
    new_conn_created = self.open()
                       ^^^^^^^^^^^
  File "/usr/local/lib/python3.11/site-packages/django/core/mail/backends/smtp.py", line 95, in open
    self.connection.login(self.username, self.password)
  File "/usr/local/lib/python3.11/smtplib.py", line 750, in login
    raise last_exception
  File "/usr/local/lib/python3.11/smtplib.py", line 739, in login
    (code, resp) = self.auth(
                   ^^^^^^^^^^
  File "/usr/local/lib/python3.11/smtplib.py", line 662, in auth
    raise SMTPAuthenticationError(code, resp)
smtplib.SMTPAuthenticationError: (535, b'5.7.8 Username and Password not accepted. For more information, go to\n5.7.8  https://support.google.com/mail/?p=BadCredentials 41be03b00d2f7-b2f5f78da0fsm1211904a12.64 - gsmtp')
ERROR 2025-06-06 14:05:36,201 basehttp 11 140183424984768 "POST /api/auth/register/ HTTP/1.0" 500 136665
INFO 2025-06-06 14:07:00,940 autoreload 11 139855135939456 Watching for file changes with StatReloader
INFO 2025-06-06 14:07:12,457 serializers 11 139855053973184 Sending verification email to sanupam2004@gmail.com
INFO 2025-06-06 14:07:12,458 serializers 11 139855053973184 Using email backend: django.core.mail.backends.smtp.EmailBackend
INFO 2025-06-06 14:07:12,458 serializers 11 139855053973184 From email: sanupam2004@gmail.com
ERROR 2025-06-06 14:07:14,867 serializers 11 139855053973184 Failed to send verification email to sanupam2004@gmail.com: (535, b'5.7.8 Username and Password not accepted. For more information, go to\n5.7.8  https://support.google.com/mail/?p=BadCredentials d9443c01a7336-23603406659sm12584695ad.186 - gsmtp')
ERROR 2025-06-06 14:07:18,406 log 11 139855053973184 Internal Server Error: /api/auth/register/
Traceback (most recent call last):
  File "/usr/local/lib/python3.11/site-packages/django/core/handlers/exception.py", line 55, in inner
    response = get_response(request)
               ^^^^^^^^^^^^^^^^^^^^^
  File "/usr/local/lib/python3.11/site-packages/django/core/handlers/base.py", line 197, in _get_response
    response = wrapped_callback(request, *callback_args, **callback_kwargs)
               ^^^^^^^^^^^^^^^^^^^^^^^^^^^^^^^^^^^^^^^^^^^^^^^^^^^^^^^^^^^^
  File "/usr/local/lib/python3.11/site-packages/django/views/decorators/csrf.py", line 65, in _view_wrapper
    return view_func(request, *args, **kwargs)
           ^^^^^^^^^^^^^^^^^^^^^^^^^^^^^^^^^^^
  File "/usr/local/lib/python3.11/site-packages/django/views/generic/base.py", line 104, in view
    return self.dispatch(request, *args, **kwargs)
           ^^^^^^^^^^^^^^^^^^^^^^^^^^^^^^^^^^^^^^^
  File "/usr/local/lib/python3.11/site-packages/rest_framework/views.py", line 509, in dispatch
    response = self.handle_exception(exc)
               ^^^^^^^^^^^^^^^^^^^^^^^^^^
  File "/usr/local/lib/python3.11/site-packages/rest_framework/views.py", line 469, in handle_exception
    self.raise_uncaught_exception(exc)
  File "/usr/local/lib/python3.11/site-packages/rest_framework/views.py", line 480, in raise_uncaught_exception
    raise exc
  File "/usr/local/lib/python3.11/site-packages/rest_framework/views.py", line 506, in dispatch
    response = handler(request, *args, **kwargs)
               ^^^^^^^^^^^^^^^^^^^^^^^^^^^^^^^^^
  File "/usr/local/lib/python3.11/site-packages/rest_framework/decorators.py", line 50, in handler
    return func(*args, **kwargs)
           ^^^^^^^^^^^^^^^^^^^^^
  File "/app/authentication/views.py", line 59, in register
    send_verification_email(user)
  File "/app/authentication/views.py", line 387, in send_verification_email
    send_mail(
  File "/usr/local/lib/python3.11/site-packages/django/core/mail/__init__.py", line 92, in send_mail
    return mail.send()
           ^^^^^^^^^^^
  File "/usr/local/lib/python3.11/site-packages/django/core/mail/message.py", line 307, in send
    return self.get_connection(fail_silently).send_messages([self])
           ^^^^^^^^^^^^^^^^^^^^^^^^^^^^^^^^^^^^^^^^^^^^^^^^^^^^^^^^
  File "/usr/local/lib/python3.11/site-packages/django/core/mail/backends/smtp.py", line 128, in send_messages
    new_conn_created = self.open()
                       ^^^^^^^^^^^
  File "/usr/local/lib/python3.11/site-packages/django/core/mail/backends/smtp.py", line 95, in open
    self.connection.login(self.username, self.password)
  File "/usr/local/lib/python3.11/smtplib.py", line 750, in login
    raise last_exception
  File "/usr/local/lib/python3.11/smtplib.py", line 739, in login
    (code, resp) = self.auth(
                   ^^^^^^^^^^
  File "/usr/local/lib/python3.11/smtplib.py", line 662, in auth
    raise SMTPAuthenticationError(code, resp)
smtplib.SMTPAuthenticationError: (535, b'5.7.8 Username and Password not accepted. For more information, go to\n5.7.8  https://support.google.com/mail/?p=BadCredentials d2e1a72fcca58-7482b0f3e59sm1334576b3a.178 - gsmtp')
ERROR 2025-06-06 14:07:18,409 basehttp 11 139855053973184 "POST /api/auth/register/ HTTP/1.0" 500 136674
INFO 2025-06-06 14:08:37,053 autoreload 11 139985277565824 Watching for file changes with StatReloader
INFO 2025-06-06 14:08:51,552 serializers 11 139985127732928 Sending verification email to sanupam2004@gmail.com
INFO 2025-06-06 14:08:51,552 serializers 11 139985127732928 Using email backend: django.core.mail.backends.smtp.EmailBackend
INFO 2025-06-06 14:08:51,552 serializers 11 139985127732928 From email: noreply@prismeet.com
INFO 2025-06-06 14:08:56,151 serializers 11 139985127732928 Verification email sent successfully to sanupam2004@gmail.com
INFO 2025-06-06 14:09:00,508 basehttp 11 139985127732928 "POST /api/auth/register/ HTTP/1.0" 201 633
INFO 2025-06-06 14:11:42,176 autoreload 11 139991256333184 Watching for file changes with StatReloader
INFO 2025-06-06 14:12:12,753 serializers 11 139991103567552 Sending verification email to accounfr4@gmail.com
INFO 2025-06-06 14:12:12,753 serializers 11 139991103567552 Using email backend: django.core.mail.backends.smtp.EmailBackend
INFO 2025-06-06 14:12:12,753 serializers 11 139991103567552 From email: noreply@prismeet.com
INFO 2025-06-06 14:12:16,306 serializers 11 139991103567552 Verification email sent successfully to accounfr4@gmail.com
INFO 2025-06-06 14:12:22,926 basehttp 11 139991103567552 "POST /api/auth/register/ HTTP/1.0" 201 631
INFO 2025-06-06 14:35:00,416 basehttp 11 139991103567552 "POST /api/auth/login/ HTTP/1.0" 200 600
INFO 2025-06-06 14:41:34,033 basehttp 11 139991103567552 "POST /api/auth/logout/ HTTP/1.0" 200 31
INFO 2025-06-06 14:45:38,110 autoreload 11 139856453925760 Watching for file changes with StatReloader
INFO 2025-06-06 14:46:58,537 basehttp 11 139856372033216 "OPTIONS /api/auth/google-auth/ HTTP/1.0" 200 0
INFO 2025-06-06 14:46:58,805 basehttp 11 139856372033216 "POST /api/auth/google-auth/ HTTP/1.0" 200 618
INFO 2025-06-06 14:53:56,638 basehttp 11 139856372033216 "GET /api/auth/profile/ HTTP/1.0" 200 513
INFO 2025-06-06 14:53:58,435 basehttp 11 139856372033216 "GET /api/auth/profile/ HTTP/1.0" 200 513
INFO 2025-06-06 14:59:42,924 autoreload 11 139856453925760 /app/authentication/views.py changed, reloading.
INFO 2025-06-06 14:59:43,725 autoreload 17 139626890447744 Watching for file changes with StatReloader
INFO 2025-06-06 15:00:39,604 autoreload 17 139626890447744 /app/authentication/serializers.py changed, reloading.
INFO 2025-06-06 15:00:40,250 autoreload 19 139735588780928 Watching for file changes with StatReloader
INFO 2025-06-06 15:01:10,563 basehttp 19 139735506872000 "GET /api/auth/profile/ HTTP/1.0" 200 511
INFO 2025-06-06 15:01:13,124 basehttp 19 139735506872000 "POST /api/auth/logout/ HTTP/1.0" 200 31
INFO 2025-06-06 15:02:06,687 basehttp 19 139735506872000 "POST /api/auth/google-auth/ HTTP/1.0" 200 710
INFO 2025-06-06 15:05:34,406 basehttp 19 139735506872000 "POST /api/auth/logout/ HTTP/1.0" 200 31
INFO 2025-06-06 15:05:40,153 basehttp 19 139735506872000 "POST /api/auth/google-auth/ HTTP/1.0" 200 710
INFO 2025-06-06 15:05:41,853 basehttp 19 139735506872000 "POST /api/auth/logout/ HTTP/1.0" 200 31
INFO 2025-06-06 15:05:47,197 basehttp 19 139735506872000 "POST /api/auth/google-auth/ HTTP/1.0" 200 712
INFO 2025-06-07 03:09:18,585 autoreload 11 139925917891456 Watching for file changes with StatReloader
INFO 2025-06-07 03:11:42,393 basehttp 11 139925835998912 "OPTIONS /api/auth/profile/ HTTP/1.0" 200 0
INFO 2025-06-07 03:11:42,443 basehttp 11 139925835998912 "GET /api/auth/profile/ HTTP/1.0" 200 607
INFO 2025-06-07 03:15:28,666 basehttp 11 139925835998912 "OPTIONS /api/auth/logout/ HTTP/1.0" 200 0
INFO 2025-06-07 03:15:28,688 basehttp 11 139925835998912 "POST /api/auth/logout/ HTTP/1.0" 200 31
INFO 2025-06-07 03:28:02,762 basehttp 11 139925835998912 "POST /api/auth/google-auth/ HTTP/1.0" 200 712
INFO 2025-06-07 03:28:08,810 basehttp 11 139925835998912 "GET /api/auth/profile/ HTTP/1.0" 200 607
INFO 2025-06-07 03:43:22,681 autoreload 11 140080267320192 Watching for file changes with StatReloader
INFO 2025-06-07 03:43:26,639 basehttp 11 140080185337536 "GET /api/auth/profile/ HTTP/1.0" 200 607
INFO 2025-06-07 03:49:26,401 basehttp 11 140080185337536 "GET /api/auth/profile/ HTTP/1.0" 200 607
INFO 2025-06-07 04:11:29,267 basehttp 11 140080185337536 "GET /api/auth/profile/ HTTP/1.0" 200 607
INFO 2025-06-07 04:11:42,205 basehttp 11 140080185337536 "PUT /api/auth/profile/ HTTP/1.0" 200 607
INFO 2025-06-07 04:11:45,830 basehttp 11 140080185337536 "GET /api/auth/profile/ HTTP/1.0" 200 607
INFO 2025-06-07 04:11:54,154 basehttp 11 140080185337536 "PUT /api/auth/profile/ HTTP/1.0" 200 607
INFO 2025-06-07 04:12:07,307 basehttp 11 140080185337536 "PUT /api/auth/profile/ HTTP/1.0" 200 607
INFO 2025-06-07 04:12:16,907 basehttp 11 140080185337536 "GET /api/auth/profile/ HTTP/1.0" 200 607
INFO 2025-06-07 04:12:31,730 basehttp 11 140080185337536 "POST /api/auth/logout/ HTTP/1.0" 200 31
INFO 2025-06-07 04:12:43,681 basehttp 11 140080185337536 "OPTIONS /api/auth/google-auth/ HTTP/1.0" 200 0
INFO 2025-06-07 04:12:43,756 basehttp 11 140080185337536 "POST /api/auth/google-auth/ HTTP/1.0" 200 710
INFO 2025-06-07 04:34:53,831 basehttp 11 140080185337536 "GET /api/auth/profile/ HTTP/1.0" 200 605
INFO 2025-06-07 04:47:51,894 basehttp 11 140080185337536 "GET /api/auth/profile/ HTTP/1.0" 200 605
INFO 2025-06-07 04:50:21,226 autoreload 11 140422655814528 Watching for file changes with StatReloader
INFO 2025-06-07 04:50:38,021 basehttp 11 140422573713088 "GET /api/auth/profile/ HTTP/1.0" 200 605
INFO 2025-06-07 04:55:41,479 autoreload 11 139734907972480 Watching for file changes with StatReloader
INFO 2025-06-07 04:56:18,652 basehttp 11 139734826346176 "GET /api/auth/profile/ HTTP/1.0" 200 605
INFO 2025-06-07 04:59:14,139 basehttp 11 139734826346176 "GET /api/auth/profile/ HTTP/1.0" 200 605
INFO 2025-06-07 04:59:24,078 basehttp 11 139734826346176 "POST /api/auth/logout/ HTTP/1.0" 200 31
INFO 2025-06-07 04:59:37,841 basehttp 11 139734826346176 "POST /api/auth/google-auth/ HTTP/1.0" 200 712
INFO 2025-06-07 05:03:52,801 basehttp 11 139734826346176 "GET /api/auth/profile/ HTTP/1.0" 200 607
INFO 2025-06-07 05:04:26,049 basehttp 11 139734826346176 "GET /api/auth/profile/ HTTP/1.0" 200 607
INFO 2025-06-07 05:07:59,070 basehttp 11 139734826346176 "GET /api/auth/profile/ HTTP/1.0" 200 607
INFO 2025-06-07 05:08:02,732 basehttp 11 139734826346176 "GET /api/auth/profile/ HTTP/1.0" 200 607
INFO 2025-06-07 05:12:09,254 autoreload 11 140311946201984 Watching for file changes with StatReloader
INFO 2025-06-07 05:12:17,570 basehttp 11 140311864010432 "OPTIONS /api/auth/profile/ HTTP/1.0" 200 0
INFO 2025-06-07 05:12:17,598 basehttp 11 140311864010432 "GET /api/auth/profile/ HTTP/1.0" 200 607
INFO 2025-06-07 05:12:24,659 basehttp 11 140311864010432 "PUT /api/auth/profile/ HTTP/1.0" 200 607
INFO 2025-06-07 05:12:25,976 basehttp 11 140311864010432 "PUT /api/auth/profile/ HTTP/1.0" 200 607
INFO 2025-06-07 05:12:27,788 basehttp 11 140311864010432 "PUT /api/auth/profile/ HTTP/1.0" 200 607
INFO 2025-06-07 05:12:28,575 basehttp 11 140311864010432 "PUT /api/auth/profile/ HTTP/1.0" 200 607
INFO 2025-06-07 05:12:55,974 basehttp 11 140311864010432 "POST /api/auth/logout/ HTTP/1.0" 200 31
INFO 2025-06-07 05:13:07,556 basehttp 11 140311864010432 "POST /api/auth/google-auth/ HTTP/1.0" 200 710
INFO 2025-06-07 06:09:54,188 basehttp 11 140311864010432 "GET /api/auth/profile/ HTTP/1.0" 200 605
INFO 2025-06-07 06:10:25,229 basehttp 11 140311864010432 "OPTIONS /api/auth/logout/ HTTP/1.0" 200 0
INFO 2025-06-07 06:10:25,249 basehttp 11 140311864010432 "POST /api/auth/logout/ HTTP/1.0" 200 31
INFO 2025-06-07 06:10:31,668 basehttp 11 140311864010432 "POST /api/auth/google-auth/ HTTP/1.0" 200 712
INFO 2025-06-07 06:11:47,137 basehttp 11 140311864010432 "GET /api/auth/profile/ HTTP/1.0" 200 607
INFO 2025-06-07 06:12:34,120 basehttp 11 140311864010432 "GET /api/auth/profile/ HTTP/1.0" 200 607
INFO 2025-06-07 06:14:28,172 basehttp 11 140311864010432 "GET /api/auth/profile/ HTTP/1.0" 200 607
INFO 2025-06-07 06:16:02,465 autoreload 10 140387185232768 Watching for file changes with StatReloader
INFO 2025-06-07 06:16:07,853 basehttp 10 140387103532736 "GET /api/auth/profile/ HTTP/1.0" 200 607
INFO 2025-06-07 07:57:55,567 basehttp 10 140387103532736 "GET /api/auth/profile/ HTTP/1.0" 200 607
INFO 2025-06-07 07:58:42,884 basehttp 10 140387103532736 "OPTIONS /api/auth/profile/ HTTP/1.0" 200 0
INFO 2025-06-07 07:58:42,900 basehttp 10 140387103532736 "GET /api/auth/profile/ HTTP/1.0" 200 607
INFO 2025-06-07 08:39:33,972 autoreload 10 140387185232768 /app/authentication/views.py changed, reloading.
INFO 2025-06-07 08:39:34,817 autoreload 16 139795715459968 Watching for file changes with StatReloader
INFO 2025-06-07 08:39:45,234 autoreload 16 139795715459968 /app/authentication/views.py changed, reloading.
INFO 2025-06-07 08:39:45,897 autoreload 18 140499879332736 Watching for file changes with StatReloader
INFO 2025-06-07 08:40:11,427 autoreload 18 140499879332736 /app/authentication/urls.py changed, reloading.
INFO 2025-06-07 08:40:12,117 autoreload 20 139968575839104 Watching for file changes with StatReloader
INFO 2025-06-07 08:40:22,496 autoreload 20 139968575839104 /app/authentication/urls.py changed, reloading.
INFO 2025-06-07 08:40:23,288 autoreload 22 140651738573696 Watching for file changes with StatReloader
INFO 2025-06-07 09:06:49,360 basehttp 22 140651589007040 "GET /api/auth/profile/ HTTP/1.0" 200 607
INFO 2025-06-07 09:54:54,126 autoreload 11 140070676814720 Watching for file changes with StatReloader
INFO 2025-06-08 04:12:42,400 autoreload 11 140454453898112 Watching for file changes with StatReloader
INFO 2025-06-08 04:12:49,953 basehttp 11 140454371780288 "OPTIONS /api/auth/profile/ HTTP/1.0" 200 0
INFO 2025-06-08 04:12:49,975 basehttp 11 140454371780288 "GET /api/auth/profile/ HTTP/1.0" 200 607
INFO 2025-06-08 04:13:00,035 basehttp 11 140454371780288 "GET /api/auth/profile/ HTTP/1.0" 200 607
INFO 2025-06-08 04:13:03,360 basehttp 11 140454371780288 "GET /api/auth/profile/ HTTP/1.0" 200 607
INFO 2025-06-08 04:16:11,802 basehttp 11 140454371780288 "GET /api/auth/profile/ HTTP/1.0" 200 607
INFO 2025-06-08 04:32:33,699 autoreload 11 140630198451072 Watching for file changes with StatReloader
INFO 2025-06-08 04:32:38,005 basehttp 11 140630047061696 "GET /api/auth/profile/ HTTP/1.0" 200 607
INFO 2025-06-08 04:41:30,866 autoreload 11 140630198451072 /app/authentication/models.py changed, reloading.
INFO 2025-06-08 04:41:31,604 autoreload 14 140190893792128 Watching for file changes with StatReloader
INFO 2025-06-08 04:42:07,293 autoreload 14 140190893792128 /app/authentication/serializers.py changed, reloading.
INFO 2025-06-08 04:42:07,965 autoreload 16 140524318063488 Watching for file changes with StatReloader
INFO 2025-06-08 04:48:53,460 autoreload 16 140524318063488 /app/authentication/views.py changed, reloading.
INFO 2025-06-08 04:48:54,192 autoreload 18 139743850896256 Watching for file changes with StatReloader
INFO 2025-06-08 04:49:19,749 autoreload 18 139743850896256 /app/authentication/urls.py changed, reloading.
INFO 2025-06-08 04:49:20,364 autoreload 20 140141597469568 Watching for file changes with StatReloader
ERROR 2025-06-08 04:54:58,692 log 20 140141512357568 Internal Server Error: /api/auth/profile/
Traceback (most recent call last):
  File "/usr/local/lib/python3.11/site-packages/django/db/backends/utils.py", line 105, in _execute
    return self.cursor.execute(sql, params)
           ^^^^^^^^^^^^^^^^^^^^^^^^^^^^^^^^
psycopg2.errors.UndefinedColumn: column auth_user.profile_picture_data does not exist
LINE 1: ...auth_user"."first_name", "auth_user"."last_name", "auth_user...
                                                             ^


The above exception was the direct cause of the following exception:

Traceback (most recent call last):
  File "/usr/local/lib/python3.11/site-packages/django/core/handlers/exception.py", line 55, in inner
    response = get_response(request)
               ^^^^^^^^^^^^^^^^^^^^^
  File "/usr/local/lib/python3.11/site-packages/django/core/handlers/base.py", line 197, in _get_response
    response = wrapped_callback(request, *callback_args, **callback_kwargs)
               ^^^^^^^^^^^^^^^^^^^^^^^^^^^^^^^^^^^^^^^^^^^^^^^^^^^^^^^^^^^^
  File "/usr/local/lib/python3.11/site-packages/django/views/decorators/csrf.py", line 65, in _view_wrapper
    return view_func(request, *args, **kwargs)
           ^^^^^^^^^^^^^^^^^^^^^^^^^^^^^^^^^^^
  File "/usr/local/lib/python3.11/site-packages/django/views/generic/base.py", line 104, in view
    return self.dispatch(request, *args, **kwargs)
           ^^^^^^^^^^^^^^^^^^^^^^^^^^^^^^^^^^^^^^^
  File "/usr/local/lib/python3.11/site-packages/rest_framework/views.py", line 509, in dispatch
    response = self.handle_exception(exc)
               ^^^^^^^^^^^^^^^^^^^^^^^^^^
  File "/usr/local/lib/python3.11/site-packages/rest_framework/views.py", line 469, in handle_exception
    self.raise_uncaught_exception(exc)
  File "/usr/local/lib/python3.11/site-packages/rest_framework/views.py", line 480, in raise_uncaught_exception
    raise exc
  File "/usr/local/lib/python3.11/site-packages/rest_framework/views.py", line 497, in dispatch
    self.initial(request, *args, **kwargs)
  File "/usr/local/lib/python3.11/site-packages/rest_framework/views.py", line 414, in initial
    self.perform_authentication(request)
  File "/usr/local/lib/python3.11/site-packages/rest_framework/views.py", line 324, in perform_authentication
    request.user
  File "/usr/local/lib/python3.11/site-packages/rest_framework/request.py", line 231, in user
    self._authenticate()
  File "/usr/local/lib/python3.11/site-packages/rest_framework/request.py", line 384, in _authenticate
    user_auth_tuple = authenticator.authenticate(self)
                      ^^^^^^^^^^^^^^^^^^^^^^^^^^^^^^^^
  File "/usr/local/lib/python3.11/site-packages/rest_framework/authentication.py", line 196, in authenticate
    return self.authenticate_credentials(token)
           ^^^^^^^^^^^^^^^^^^^^^^^^^^^^^^^^^^^^
  File "/usr/local/lib/python3.11/site-packages/rest_framework/authentication.py", line 201, in authenticate_credentials
    token = model.objects.select_related('user').get(key=key)
            ^^^^^^^^^^^^^^^^^^^^^^^^^^^^^^^^^^^^^^^^^^^^^^^^^
  File "/usr/local/lib/python3.11/site-packages/django/db/models/query.py", line 629, in get
    num = len(clone)
          ^^^^^^^^^^
  File "/usr/local/lib/python3.11/site-packages/django/db/models/query.py", line 366, in __len__
    self._fetch_all()
  File "/usr/local/lib/python3.11/site-packages/django/db/models/query.py", line 1945, in _fetch_all
    self._result_cache = list(self._iterable_class(self))
                         ^^^^^^^^^^^^^^^^^^^^^^^^^^^^^^^^
  File "/usr/local/lib/python3.11/site-packages/django/db/models/query.py", line 91, in __iter__
    results = compiler.execute_sql(
              ^^^^^^^^^^^^^^^^^^^^^
  File "/usr/local/lib/python3.11/site-packages/django/db/models/sql/compiler.py", line 1623, in execute_sql
    cursor.execute(sql, params)
  File "/usr/local/lib/python3.11/site-packages/django/db/backends/utils.py", line 122, in execute
    return super().execute(sql, params)
           ^^^^^^^^^^^^^^^^^^^^^^^^^^^^
  File "/usr/local/lib/python3.11/site-packages/django/db/backends/utils.py", line 79, in execute
    return self._execute_with_wrappers(
           ^^^^^^^^^^^^^^^^^^^^^^^^^^^^
  File "/usr/local/lib/python3.11/site-packages/django/db/backends/utils.py", line 92, in _execute_with_wrappers
    return executor(sql, params, many, context)
           ^^^^^^^^^^^^^^^^^^^^^^^^^^^^^^^^^^^^
  File "/usr/local/lib/python3.11/site-packages/django/db/backends/utils.py", line 100, in _execute
    with self.db.wrap_database_errors:
  File "/usr/local/lib/python3.11/site-packages/django/db/utils.py", line 91, in __exit__
    raise dj_exc_value.with_traceback(traceback) from exc_value
  File "/usr/local/lib/python3.11/site-packages/django/db/backends/utils.py", line 105, in _execute
    return self.cursor.execute(sql, params)
           ^^^^^^^^^^^^^^^^^^^^^^^^^^^^^^^^
django.db.utils.ProgrammingError: column auth_user.profile_picture_data does not exist
LINE 1: ...auth_user"."first_name", "auth_user"."last_name", "auth_user...
                                                             ^

ERROR 2025-06-08 04:54:58,696 basehttp 20 140141512357568 "GET /api/auth/profile/ HTTP/1.0" 500 182755
INFO 2025-06-08 04:54:58,700 basehttp 20 140141512357568 "OPTIONS /api/auth/logout/ HTTP/1.0" 200 0
ERROR 2025-06-08 04:54:58,731 log 20 140141512357568 Internal Server Error: /api/auth/logout/
Traceback (most recent call last):
  File "/usr/local/lib/python3.11/site-packages/django/db/backends/utils.py", line 105, in _execute
    return self.cursor.execute(sql, params)
           ^^^^^^^^^^^^^^^^^^^^^^^^^^^^^^^^
psycopg2.errors.UndefinedColumn: column auth_user.profile_picture_data does not exist
LINE 1: ...auth_user"."first_name", "auth_user"."last_name", "auth_user...
                                                             ^


The above exception was the direct cause of the following exception:

Traceback (most recent call last):
  File "/usr/local/lib/python3.11/site-packages/django/core/handlers/exception.py", line 55, in inner
    response = get_response(request)
               ^^^^^^^^^^^^^^^^^^^^^
  File "/usr/local/lib/python3.11/site-packages/django/core/handlers/base.py", line 197, in _get_response
    response = wrapped_callback(request, *callback_args, **callback_kwargs)
               ^^^^^^^^^^^^^^^^^^^^^^^^^^^^^^^^^^^^^^^^^^^^^^^^^^^^^^^^^^^^
  File "/usr/local/lib/python3.11/site-packages/django/views/decorators/csrf.py", line 65, in _view_wrapper
    return view_func(request, *args, **kwargs)
           ^^^^^^^^^^^^^^^^^^^^^^^^^^^^^^^^^^^
  File "/usr/local/lib/python3.11/site-packages/django/views/generic/base.py", line 104, in view
    return self.dispatch(request, *args, **kwargs)
           ^^^^^^^^^^^^^^^^^^^^^^^^^^^^^^^^^^^^^^^
  File "/usr/local/lib/python3.11/site-packages/rest_framework/views.py", line 509, in dispatch
    response = self.handle_exception(exc)
               ^^^^^^^^^^^^^^^^^^^^^^^^^^
  File "/usr/local/lib/python3.11/site-packages/rest_framework/views.py", line 469, in handle_exception
    self.raise_uncaught_exception(exc)
  File "/usr/local/lib/python3.11/site-packages/rest_framework/views.py", line 480, in raise_uncaught_exception
    raise exc
  File "/usr/local/lib/python3.11/site-packages/rest_framework/views.py", line 497, in dispatch
    self.initial(request, *args, **kwargs)
  File "/usr/local/lib/python3.11/site-packages/rest_framework/views.py", line 414, in initial
    self.perform_authentication(request)
  File "/usr/local/lib/python3.11/site-packages/rest_framework/views.py", line 324, in perform_authentication
    request.user
  File "/usr/local/lib/python3.11/site-packages/rest_framework/request.py", line 231, in user
    self._authenticate()
  File "/usr/local/lib/python3.11/site-packages/rest_framework/request.py", line 384, in _authenticate
    user_auth_tuple = authenticator.authenticate(self)
                      ^^^^^^^^^^^^^^^^^^^^^^^^^^^^^^^^
  File "/usr/local/lib/python3.11/site-packages/rest_framework/authentication.py", line 196, in authenticate
    return self.authenticate_credentials(token)
           ^^^^^^^^^^^^^^^^^^^^^^^^^^^^^^^^^^^^
  File "/usr/local/lib/python3.11/site-packages/rest_framework/authentication.py", line 201, in authenticate_credentials
    token = model.objects.select_related('user').get(key=key)
            ^^^^^^^^^^^^^^^^^^^^^^^^^^^^^^^^^^^^^^^^^^^^^^^^^
  File "/usr/local/lib/python3.11/site-packages/django/db/models/query.py", line 629, in get
    num = len(clone)
          ^^^^^^^^^^
  File "/usr/local/lib/python3.11/site-packages/django/db/models/query.py", line 366, in __len__
    self._fetch_all()
  File "/usr/local/lib/python3.11/site-packages/django/db/models/query.py", line 1945, in _fetch_all
    self._result_cache = list(self._iterable_class(self))
                         ^^^^^^^^^^^^^^^^^^^^^^^^^^^^^^^^
  File "/usr/local/lib/python3.11/site-packages/django/db/models/query.py", line 91, in __iter__
    results = compiler.execute_sql(
              ^^^^^^^^^^^^^^^^^^^^^
  File "/usr/local/lib/python3.11/site-packages/django/db/models/sql/compiler.py", line 1623, in execute_sql
    cursor.execute(sql, params)
  File "/usr/local/lib/python3.11/site-packages/django/db/backends/utils.py", line 122, in execute
    return super().execute(sql, params)
           ^^^^^^^^^^^^^^^^^^^^^^^^^^^^
  File "/usr/local/lib/python3.11/site-packages/django/db/backends/utils.py", line 79, in execute
    return self._execute_with_wrappers(
           ^^^^^^^^^^^^^^^^^^^^^^^^^^^^
  File "/usr/local/lib/python3.11/site-packages/django/db/backends/utils.py", line 92, in _execute_with_wrappers
    return executor(sql, params, many, context)
           ^^^^^^^^^^^^^^^^^^^^^^^^^^^^^^^^^^^^
  File "/usr/local/lib/python3.11/site-packages/django/db/backends/utils.py", line 100, in _execute
    with self.db.wrap_database_errors:
  File "/usr/local/lib/python3.11/site-packages/django/db/utils.py", line 91, in __exit__
    raise dj_exc_value.with_traceback(traceback) from exc_value
  File "/usr/local/lib/python3.11/site-packages/django/db/backends/utils.py", line 105, in _execute
    return self.cursor.execute(sql, params)
           ^^^^^^^^^^^^^^^^^^^^^^^^^^^^^^^^
django.db.utils.ProgrammingError: column auth_user.profile_picture_data does not exist
LINE 1: ...auth_user"."first_name", "auth_user"."last_name", "auth_user...
                                                             ^

ERROR 2025-06-08 04:54:58,733 basehttp 20 140141512357568 "POST /api/auth/logout/ HTTP/1.0" 500 182745
INFO 2025-06-08 04:55:13,460 basehttp 20 140141512357568 "OPTIONS /api/auth/google-auth/ HTTP/1.0" 200 0
ERROR 2025-06-08 04:55:13,589 log 20 140141512357568 Internal Server Error: /api/auth/google-auth/
Traceback (most recent call last):
  File "/usr/local/lib/python3.11/site-packages/django/db/backends/utils.py", line 105, in _execute
    return self.cursor.execute(sql, params)
           ^^^^^^^^^^^^^^^^^^^^^^^^^^^^^^^^
psycopg2.errors.UndefinedColumn: column auth_user.profile_picture_data does not exist
LINE 1: ...auth_user"."first_name", "auth_user"."last_name", "auth_user...
                                                             ^


The above exception was the direct cause of the following exception:

Traceback (most recent call last):
  File "/usr/local/lib/python3.11/site-packages/django/core/handlers/exception.py", line 55, in inner
    response = get_response(request)
               ^^^^^^^^^^^^^^^^^^^^^
  File "/usr/local/lib/python3.11/site-packages/django/core/handlers/base.py", line 197, in _get_response
    response = wrapped_callback(request, *callback_args, **callback_kwargs)
               ^^^^^^^^^^^^^^^^^^^^^^^^^^^^^^^^^^^^^^^^^^^^^^^^^^^^^^^^^^^^
  File "/usr/local/lib/python3.11/site-packages/django/views/decorators/csrf.py", line 65, in _view_wrapper
    return view_func(request, *args, **kwargs)
           ^^^^^^^^^^^^^^^^^^^^^^^^^^^^^^^^^^^
  File "/usr/local/lib/python3.11/site-packages/django/views/generic/base.py", line 104, in view
    return self.dispatch(request, *args, **kwargs)
           ^^^^^^^^^^^^^^^^^^^^^^^^^^^^^^^^^^^^^^^
  File "/usr/local/lib/python3.11/site-packages/rest_framework/views.py", line 509, in dispatch
    response = self.handle_exception(exc)
               ^^^^^^^^^^^^^^^^^^^^^^^^^^
  File "/usr/local/lib/python3.11/site-packages/rest_framework/views.py", line 469, in handle_exception
    self.raise_uncaught_exception(exc)
  File "/usr/local/lib/python3.11/site-packages/rest_framework/views.py", line 480, in raise_uncaught_exception
    raise exc
  File "/usr/local/lib/python3.11/site-packages/rest_framework/views.py", line 506, in dispatch
    response = handler(request, *args, **kwargs)
               ^^^^^^^^^^^^^^^^^^^^^^^^^^^^^^^^^
  File "/usr/local/lib/python3.11/site-packages/rest_framework/decorators.py", line 50, in handler
    return func(*args, **kwargs)
           ^^^^^^^^^^^^^^^^^^^^^
  File "/app/authentication/views.py", line 146, in google_auth
    user = User.objects.get(email=email)
           ^^^^^^^^^^^^^^^^^^^^^^^^^^^^^
  File "/usr/local/lib/python3.11/site-packages/django/db/models/manager.py", line 87, in manager_method
    return getattr(self.get_queryset(), name)(*args, **kwargs)
           ^^^^^^^^^^^^^^^^^^^^^^^^^^^^^^^^^^^^^^^^^^^^^^^^^^^
  File "/usr/local/lib/python3.11/site-packages/django/db/models/query.py", line 629, in get
    num = len(clone)
          ^^^^^^^^^^
  File "/usr/local/lib/python3.11/site-packages/django/db/models/query.py", line 366, in __len__
    self._fetch_all()
  File "/usr/local/lib/python3.11/site-packages/django/db/models/query.py", line 1945, in _fetch_all
    self._result_cache = list(self._iterable_class(self))
                         ^^^^^^^^^^^^^^^^^^^^^^^^^^^^^^^^
  File "/usr/local/lib/python3.11/site-packages/django/db/models/query.py", line 91, in __iter__
    results = compiler.execute_sql(
              ^^^^^^^^^^^^^^^^^^^^^
  File "/usr/local/lib/python3.11/site-packages/django/db/models/sql/compiler.py", line 1623, in execute_sql
    cursor.execute(sql, params)
  File "/usr/local/lib/python3.11/site-packages/django/db/backends/utils.py", line 122, in execute
    return super().execute(sql, params)
           ^^^^^^^^^^^^^^^^^^^^^^^^^^^^
  File "/usr/local/lib/python3.11/site-packages/django/db/backends/utils.py", line 79, in execute
    return self._execute_with_wrappers(
           ^^^^^^^^^^^^^^^^^^^^^^^^^^^^
  File "/usr/local/lib/python3.11/site-packages/django/db/backends/utils.py", line 92, in _execute_with_wrappers
    return executor(sql, params, many, context)
           ^^^^^^^^^^^^^^^^^^^^^^^^^^^^^^^^^^^^
  File "/usr/local/lib/python3.11/site-packages/django/db/backends/utils.py", line 100, in _execute
    with self.db.wrap_database_errors:
  File "/usr/local/lib/python3.11/site-packages/django/db/utils.py", line 91, in __exit__
    raise dj_exc_value.with_traceback(traceback) from exc_value
  File "/usr/local/lib/python3.11/site-packages/django/db/backends/utils.py", line 105, in _execute
    return self.cursor.execute(sql, params)
           ^^^^^^^^^^^^^^^^^^^^^^^^^^^^^^^^
django.db.utils.ProgrammingError: column auth_user.profile_picture_data does not exist
LINE 1: ...auth_user"."first_name", "auth_user"."last_name", "auth_user...
                                                             ^

ERROR 2025-06-08 04:55:13,592 basehttp 20 140141512357568 "POST /api/auth/google-auth/ HTTP/1.0" 500 172689
INFO 2025-06-08 05:04:45,767 autoreload 11 140714672028544 Watching for file changes with StatReloader
INFO 2025-06-08 05:04:59,625 basehttp 11 140714587453120 "POST /api/auth/google-auth/ HTTP/1.0" 200 618
INFO 2025-06-08 05:05:11,882 basehttp 11 140714587453120 "OPTIONS /api/auth/profile/picture/upload/ HTTP/1.0" 200 0
INFO 2025-06-08 05:05:12,081 views 11 140714587453120 Profile picture uploaded successfully for user sanupam2004@gmail.com
INFO 2025-06-08 05:05:12,083 basehttp 11 140714587453120 "POST /api/auth/profile/picture/upload/ HTTP/1.0" 200 110982
INFO 2025-06-08 05:05:12,105 basehttp 11 140714587453120 "GET /api/auth/profile/ HTTP/1.0" 200 111421
INFO 2025-06-08 05:09:17,616 basehttp 11 140714587453120 "GET /api/auth/profile/ HTTP/1.0" 200 111421
INFO 2025-06-08 05:09:32,242 basehttp 11 140714587453120 "GET /api/auth/profile/ HTTP/1.0" 200 111421
INFO 2025-06-08 05:10:56,437 basehttp 11 140714587453120 "GET /api/auth/profile/ HTTP/1.0" 200 111421
INFO 2025-06-08 05:11:03,703 basehttp 11 140714587453120 "GET /api/auth/profile/ HTTP/1.0" 200 111421
INFO 2025-06-08 05:11:07,968 basehttp 11 140714587453120 "GET /api/auth/profile/ HTTP/1.0" 200 111421
INFO 2025-06-08 05:11:11,268 basehttp 11 140714587453120 "GET /api/auth/profile/ HTTP/1.0" 200 111421
INFO 2025-06-08 05:11:16,881 basehttp 11 140714587453120 "OPTIONS /api/auth/profile/picture/delete/ HTTP/1.0" 200 0
INFO 2025-06-08 05:11:16,908 views 11 140714587453120 Profile picture deleted successfully for user sanupam2004@gmail.com
INFO 2025-06-08 05:11:16,909 basehttp 11 140714587453120 "DELETE /api/auth/profile/picture/delete/ HTTP/1.0" 200 50
INFO 2025-06-08 05:11:16,922 basehttp 11 140714587453120 "GET /api/auth/profile/ HTTP/1.0" 200 513
INFO 2025-06-08 05:11:16,936 basehttp 11 140714587453120 "GET /api/auth/profile/ HTTP/1.0" 200 513
INFO 2025-06-08 05:11:30,772 views 11 140714587453120 Profile picture uploaded successfully for user sanupam2004@gmail.com
INFO 2025-06-08 05:11:30,779 basehttp 11 140714587453120 "POST /api/auth/profile/picture/upload/ HTTP/1.0" 200 649586
INFO 2025-06-08 05:11:30,810 basehttp 11 140714587453120 "GET /api/auth/profile/ HTTP/1.0" 200 650025
INFO 2025-06-08 05:11:30,855 basehttp 11 140714587453120 "GET /api/auth/profile/ HTTP/1.0" 200 650025
INFO 2025-06-08 05:11:35,861 basehttp 11 140714587453120 "GET /api/auth/profile/ HTTP/1.0" 200 650025
INFO 2025-06-08 05:11:55,464 basehttp 11 140714587453120 "GET /api/auth/profile/ HTTP/1.0" 200 650025
INFO 2025-06-08 05:13:47,313 basehttp 11 140714587453120 "PUT /api/auth/profile/ HTTP/1.0" 200 650025
