INFO 2025-06-02 12:20:25,742 autoreload 846108 130003624698944 Watching for file changes with StatReloader
INFO 2025-06-04 03:49:46,347 autoreload 11 140643776711552 Watching for file changes with StatReloader
INFO 2025-06-04 03:51:38,980 autoreload 11 139667068795776 Watching for file changes with StatReloader
INFO 2025-06-04 03:54:40,373 autoreload 11 140492161502080 Watching for file changes with StatReloader
INFO 2025-06-04 04:03:31,365 basehttp 11 140492004128448 "GET /api/auth/google-auth HTTP/1.0" 301 0
WARNING 2025-06-04 04:03:31,369 log 11 140492004128448 Method Not Allowed: /api/auth/google-auth/
WARNING 2025-06-04 04:03:31,370 basehttp 11 140492004128448 "GET /api/auth/google-auth/ HTTP/1.0" 405 40
WARNING 2025-06-04 04:03:43,917 log 11 140492004128448 Method Not Allowed: /api/auth/login/
WARNING 2025-06-04 04:03:43,918 basehttp 11 140492004128448 "GET /api/auth/login/ HTTP/1.0" 405 40
WARNING 2025-06-04 04:08:12,778 log 11 140492004128448 Method Not Allowed: /api/auth/login/
WARNING 2025-06-04 04:08:12,779 basehttp 11 140492004128448 "GET /api/auth/login/ HTTP/1.0" 405 40
WARNING 2025-06-04 04:11:36,466 log 11 140492004128448 Bad Request: /api/auth/register/
WARNING 2025-06-04 04:11:36,466 basehttp 11 140492004128448 "POST /api/auth/register/ HTTP/1.0" 400 129
ERROR 2025-06-04 04:13:24,857 log 11 140492004128448 Internal Server Error: /api/auth/register/
Traceback (most recent call last):
  File "/usr/local/lib/python3.11/site-packages/django/db/backends/utils.py", line 105, in _execute
    return self.cursor.execute(sql, params)
           ^^^^^^^^^^^^^^^^^^^^^^^^^^^^^^^^
psycopg2.errors.UniqueViolation: duplicate key value violates unique constraint "authentication_userprofile_user_id_key"
DETAIL:  Key (user_id)=(9c8058f3-cbd5-4be1-a84a-5fbfafa779aa) already exists.


The above exception was the direct cause of the following exception:

Traceback (most recent call last):
  File "/usr/local/lib/python3.11/site-packages/django/core/handlers/exception.py", line 55, in inner
    response = get_response(request)
               ^^^^^^^^^^^^^^^^^^^^^
  File "/usr/local/lib/python3.11/site-packages/django/core/handlers/base.py", line 197, in _get_response
    response = wrapped_callback(request, *callback_args, **callback_kwargs)
               ^^^^^^^^^^^^^^^^^^^^^^^^^^^^^^^^^^^^^^^^^^^^^^^^^^^^^^^^^^^^
  File "/usr/local/lib/python3.11/site-packages/django/views/decorators/csrf.py", line 65, in _view_wrapper
    return view_func(request, *args, **kwargs)
           ^^^^^^^^^^^^^^^^^^^^^^^^^^^^^^^^^^^
  File "/usr/local/lib/python3.11/site-packages/django/views/generic/base.py", line 104, in view
    return self.dispatch(request, *args, **kwargs)
           ^^^^^^^^^^^^^^^^^^^^^^^^^^^^^^^^^^^^^^^
  File "/usr/local/lib/python3.11/site-packages/rest_framework/views.py", line 509, in dispatch
    response = self.handle_exception(exc)
               ^^^^^^^^^^^^^^^^^^^^^^^^^^
  File "/usr/local/lib/python3.11/site-packages/rest_framework/views.py", line 469, in handle_exception
    self.raise_uncaught_exception(exc)
  File "/usr/local/lib/python3.11/site-packages/rest_framework/views.py", line 480, in raise_uncaught_exception
    raise exc
  File "/usr/local/lib/python3.11/site-packages/rest_framework/views.py", line 506, in dispatch
    response = handler(request, *args, **kwargs)
               ^^^^^^^^^^^^^^^^^^^^^^^^^^^^^^^^^
  File "/usr/local/lib/python3.11/site-packages/rest_framework/decorators.py", line 50, in handler
    return func(*args, **kwargs)
           ^^^^^^^^^^^^^^^^^^^^^
  File "/app/authentication/views.py", line 56, in register
    user = serializer.save()
           ^^^^^^^^^^^^^^^^^
  File "/usr/local/lib/python3.11/site-packages/rest_framework/serializers.py", line 208, in save
    self.instance = self.create(validated_data)
                    ^^^^^^^^^^^^^^^^^^^^^^^^^^^
  File "/app/authentication/serializers.py", line 51, in create
    UserProfile.objects.create(user=user)
  File "/usr/local/lib/python3.11/site-packages/django/db/models/manager.py", line 87, in manager_method
    return getattr(self.get_queryset(), name)(*args, **kwargs)
           ^^^^^^^^^^^^^^^^^^^^^^^^^^^^^^^^^^^^^^^^^^^^^^^^^^^
  File "/usr/local/lib/python3.11/site-packages/django/db/models/query.py", line 663, in create
    obj.save(force_insert=True, using=self.db)
  File "/usr/local/lib/python3.11/site-packages/django/db/models/base.py", line 902, in save
    self.save_base(
  File "/usr/local/lib/python3.11/site-packages/django/db/models/base.py", line 1008, in save_base
    updated = self._save_table(
              ^^^^^^^^^^^^^^^^^
  File "/usr/local/lib/python3.11/site-packages/django/db/models/base.py", line 1169, in _save_table
    results = self._do_insert(
              ^^^^^^^^^^^^^^^^
  File "/usr/local/lib/python3.11/site-packages/django/db/models/base.py", line 1210, in _do_insert
    return manager._insert(
           ^^^^^^^^^^^^^^^^
  File "/usr/local/lib/python3.11/site-packages/django/db/models/manager.py", line 87, in manager_method
    return getattr(self.get_queryset(), name)(*args, **kwargs)
           ^^^^^^^^^^^^^^^^^^^^^^^^^^^^^^^^^^^^^^^^^^^^^^^^^^^
  File "/usr/local/lib/python3.11/site-packages/django/db/models/query.py", line 1864, in _insert
    return query.get_compiler(using=using).execute_sql(returning_fields)
           ^^^^^^^^^^^^^^^^^^^^^^^^^^^^^^^^^^^^^^^^^^^^^^^^^^^^^^^^^^^^^
  File "/usr/local/lib/python3.11/site-packages/django/db/models/sql/compiler.py", line 1882, in execute_sql
    cursor.execute(sql, params)
  File "/usr/local/lib/python3.11/site-packages/django/db/backends/utils.py", line 122, in execute
    return super().execute(sql, params)
           ^^^^^^^^^^^^^^^^^^^^^^^^^^^^
  File "/usr/local/lib/python3.11/site-packages/django/db/backends/utils.py", line 79, in execute
    return self._execute_with_wrappers(
           ^^^^^^^^^^^^^^^^^^^^^^^^^^^^
  File "/usr/local/lib/python3.11/site-packages/django/db/backends/utils.py", line 92, in _execute_with_wrappers
    return executor(sql, params, many, context)
           ^^^^^^^^^^^^^^^^^^^^^^^^^^^^^^^^^^^^
  File "/usr/local/lib/python3.11/site-packages/django/db/backends/utils.py", line 100, in _execute
    with self.db.wrap_database_errors:
  File "/usr/local/lib/python3.11/site-packages/django/db/utils.py", line 91, in __exit__
    raise dj_exc_value.with_traceback(traceback) from exc_value
  File "/usr/local/lib/python3.11/site-packages/django/db/backends/utils.py", line 105, in _execute
    return self.cursor.execute(sql, params)
           ^^^^^^^^^^^^^^^^^^^^^^^^^^^^^^^^
django.db.utils.IntegrityError: duplicate key value violates unique constraint "authentication_userprofile_user_id_key"
DETAIL:  Key (user_id)=(9c8058f3-cbd5-4be1-a84a-5fbfafa779aa) already exists.

ERROR 2025-06-04 04:13:24,861 basehttp 11 140492004128448 "POST /api/auth/register/ HTTP/1.0" 500 190047
ERROR 2025-06-04 04:14:33,624 log 11 140492004128448 Internal Server Error: /api/auth/register/
Traceback (most recent call last):
  File "/usr/local/lib/python3.11/site-packages/django/db/backends/utils.py", line 105, in _execute
    return self.cursor.execute(sql, params)
           ^^^^^^^^^^^^^^^^^^^^^^^^^^^^^^^^
psycopg2.errors.UniqueViolation: duplicate key value violates unique constraint "authentication_userprofile_user_id_key"
DETAIL:  Key (user_id)=(6071496f-8351-4940-ade6-09860d97c238) already exists.


The above exception was the direct cause of the following exception:

Traceback (most recent call last):
  File "/usr/local/lib/python3.11/site-packages/django/core/handlers/exception.py", line 55, in inner
    response = get_response(request)
               ^^^^^^^^^^^^^^^^^^^^^
  File "/usr/local/lib/python3.11/site-packages/django/core/handlers/base.py", line 197, in _get_response
    response = wrapped_callback(request, *callback_args, **callback_kwargs)
               ^^^^^^^^^^^^^^^^^^^^^^^^^^^^^^^^^^^^^^^^^^^^^^^^^^^^^^^^^^^^
  File "/usr/local/lib/python3.11/site-packages/django/views/decorators/csrf.py", line 65, in _view_wrapper
    return view_func(request, *args, **kwargs)
           ^^^^^^^^^^^^^^^^^^^^^^^^^^^^^^^^^^^
  File "/usr/local/lib/python3.11/site-packages/django/views/generic/base.py", line 104, in view
    return self.dispatch(request, *args, **kwargs)
           ^^^^^^^^^^^^^^^^^^^^^^^^^^^^^^^^^^^^^^^
  File "/usr/local/lib/python3.11/site-packages/rest_framework/views.py", line 509, in dispatch
    response = self.handle_exception(exc)
               ^^^^^^^^^^^^^^^^^^^^^^^^^^
  File "/usr/local/lib/python3.11/site-packages/rest_framework/views.py", line 469, in handle_exception
    self.raise_uncaught_exception(exc)
  File "/usr/local/lib/python3.11/site-packages/rest_framework/views.py", line 480, in raise_uncaught_exception
    raise exc
  File "/usr/local/lib/python3.11/site-packages/rest_framework/views.py", line 506, in dispatch
    response = handler(request, *args, **kwargs)
               ^^^^^^^^^^^^^^^^^^^^^^^^^^^^^^^^^
  File "/usr/local/lib/python3.11/site-packages/rest_framework/decorators.py", line 50, in handler
    return func(*args, **kwargs)
           ^^^^^^^^^^^^^^^^^^^^^
  File "/app/authentication/views.py", line 56, in register
    user = serializer.save()
           ^^^^^^^^^^^^^^^^^
  File "/usr/local/lib/python3.11/site-packages/rest_framework/serializers.py", line 208, in save
    self.instance = self.create(validated_data)
                    ^^^^^^^^^^^^^^^^^^^^^^^^^^^
  File "/app/authentication/serializers.py", line 51, in create
    UserProfile.objects.create(user=user)
  File "/usr/local/lib/python3.11/site-packages/django/db/models/manager.py", line 87, in manager_method
    return getattr(self.get_queryset(), name)(*args, **kwargs)
           ^^^^^^^^^^^^^^^^^^^^^^^^^^^^^^^^^^^^^^^^^^^^^^^^^^^
  File "/usr/local/lib/python3.11/site-packages/django/db/models/query.py", line 663, in create
    obj.save(force_insert=True, using=self.db)
  File "/usr/local/lib/python3.11/site-packages/django/db/models/base.py", line 902, in save
    self.save_base(
  File "/usr/local/lib/python3.11/site-packages/django/db/models/base.py", line 1008, in save_base
    updated = self._save_table(
              ^^^^^^^^^^^^^^^^^
  File "/usr/local/lib/python3.11/site-packages/django/db/models/base.py", line 1169, in _save_table
    results = self._do_insert(
              ^^^^^^^^^^^^^^^^
  File "/usr/local/lib/python3.11/site-packages/django/db/models/base.py", line 1210, in _do_insert
    return manager._insert(
           ^^^^^^^^^^^^^^^^
  File "/usr/local/lib/python3.11/site-packages/django/db/models/manager.py", line 87, in manager_method
    return getattr(self.get_queryset(), name)(*args, **kwargs)
           ^^^^^^^^^^^^^^^^^^^^^^^^^^^^^^^^^^^^^^^^^^^^^^^^^^^
  File "/usr/local/lib/python3.11/site-packages/django/db/models/query.py", line 1864, in _insert
    return query.get_compiler(using=using).execute_sql(returning_fields)
           ^^^^^^^^^^^^^^^^^^^^^^^^^^^^^^^^^^^^^^^^^^^^^^^^^^^^^^^^^^^^^
  File "/usr/local/lib/python3.11/site-packages/django/db/models/sql/compiler.py", line 1882, in execute_sql
    cursor.execute(sql, params)
  File "/usr/local/lib/python3.11/site-packages/django/db/backends/utils.py", line 122, in execute
    return super().execute(sql, params)
           ^^^^^^^^^^^^^^^^^^^^^^^^^^^^
  File "/usr/local/lib/python3.11/site-packages/django/db/backends/utils.py", line 79, in execute
    return self._execute_with_wrappers(
           ^^^^^^^^^^^^^^^^^^^^^^^^^^^^
  File "/usr/local/lib/python3.11/site-packages/django/db/backends/utils.py", line 92, in _execute_with_wrappers
    return executor(sql, params, many, context)
           ^^^^^^^^^^^^^^^^^^^^^^^^^^^^^^^^^^^^
  File "/usr/local/lib/python3.11/site-packages/django/db/backends/utils.py", line 100, in _execute
    with self.db.wrap_database_errors:
  File "/usr/local/lib/python3.11/site-packages/django/db/utils.py", line 91, in __exit__
    raise dj_exc_value.with_traceback(traceback) from exc_value
  File "/usr/local/lib/python3.11/site-packages/django/db/backends/utils.py", line 105, in _execute
    return self.cursor.execute(sql, params)
           ^^^^^^^^^^^^^^^^^^^^^^^^^^^^^^^^
django.db.utils.IntegrityError: duplicate key value violates unique constraint "authentication_userprofile_user_id_key"
DETAIL:  Key (user_id)=(6071496f-8351-4940-ade6-09860d97c238) already exists.

ERROR 2025-06-04 04:14:33,626 basehttp 11 140492004128448 "POST /api/auth/register/ HTTP/1.0" 500 190062
INFO 2025-06-04 04:18:31,940 autoreload 11 140307725712256 Watching for file changes with StatReloader
ERROR 2025-06-04 04:20:35,380 log 11 140307643492032 Internal Server Error: /api/auth/register/
Traceback (most recent call last):
  File "/usr/local/lib/python3.11/site-packages/django/db/backends/utils.py", line 105, in _execute
    return self.cursor.execute(sql, params)
           ^^^^^^^^^^^^^^^^^^^^^^^^^^^^^^^^
psycopg2.errors.UniqueViolation: duplicate key value violates unique constraint "authentication_userprofile_user_id_key"
DETAIL:  Key (user_id)=(2df45b91-5448-41a2-950e-2ac598127d3f) already exists.


The above exception was the direct cause of the following exception:

Traceback (most recent call last):
  File "/usr/local/lib/python3.11/site-packages/django/core/handlers/exception.py", line 55, in inner
    response = get_response(request)
               ^^^^^^^^^^^^^^^^^^^^^
  File "/usr/local/lib/python3.11/site-packages/django/core/handlers/base.py", line 197, in _get_response
    response = wrapped_callback(request, *callback_args, **callback_kwargs)
               ^^^^^^^^^^^^^^^^^^^^^^^^^^^^^^^^^^^^^^^^^^^^^^^^^^^^^^^^^^^^
  File "/usr/local/lib/python3.11/site-packages/django/views/decorators/csrf.py", line 65, in _view_wrapper
    return view_func(request, *args, **kwargs)
           ^^^^^^^^^^^^^^^^^^^^^^^^^^^^^^^^^^^
  File "/usr/local/lib/python3.11/site-packages/django/views/generic/base.py", line 104, in view
    return self.dispatch(request, *args, **kwargs)
           ^^^^^^^^^^^^^^^^^^^^^^^^^^^^^^^^^^^^^^^
  File "/usr/local/lib/python3.11/site-packages/rest_framework/views.py", line 509, in dispatch
    response = self.handle_exception(exc)
               ^^^^^^^^^^^^^^^^^^^^^^^^^^
  File "/usr/local/lib/python3.11/site-packages/rest_framework/views.py", line 469, in handle_exception
    self.raise_uncaught_exception(exc)
  File "/usr/local/lib/python3.11/site-packages/rest_framework/views.py", line 480, in raise_uncaught_exception
    raise exc
  File "/usr/local/lib/python3.11/site-packages/rest_framework/views.py", line 506, in dispatch
    response = handler(request, *args, **kwargs)
               ^^^^^^^^^^^^^^^^^^^^^^^^^^^^^^^^^
  File "/usr/local/lib/python3.11/site-packages/rest_framework/decorators.py", line 50, in handler
    return func(*args, **kwargs)
           ^^^^^^^^^^^^^^^^^^^^^
  File "/app/authentication/views.py", line 56, in register
    user = serializer.save()
           ^^^^^^^^^^^^^^^^^
  File "/usr/local/lib/python3.11/site-packages/rest_framework/serializers.py", line 208, in save
    self.instance = self.create(validated_data)
                    ^^^^^^^^^^^^^^^^^^^^^^^^^^^
  File "/app/authentication/serializers.py", line 51, in create
    UserProfile.objects.create(user=user)
  File "/usr/local/lib/python3.11/site-packages/django/db/models/manager.py", line 87, in manager_method
    return getattr(self.get_queryset(), name)(*args, **kwargs)
           ^^^^^^^^^^^^^^^^^^^^^^^^^^^^^^^^^^^^^^^^^^^^^^^^^^^
  File "/usr/local/lib/python3.11/site-packages/django/db/models/query.py", line 663, in create
    obj.save(force_insert=True, using=self.db)
  File "/usr/local/lib/python3.11/site-packages/django/db/models/base.py", line 902, in save
    self.save_base(
  File "/usr/local/lib/python3.11/site-packages/django/db/models/base.py", line 1008, in save_base
    updated = self._save_table(
              ^^^^^^^^^^^^^^^^^
  File "/usr/local/lib/python3.11/site-packages/django/db/models/base.py", line 1169, in _save_table
    results = self._do_insert(
              ^^^^^^^^^^^^^^^^
  File "/usr/local/lib/python3.11/site-packages/django/db/models/base.py", line 1210, in _do_insert
    return manager._insert(
           ^^^^^^^^^^^^^^^^
  File "/usr/local/lib/python3.11/site-packages/django/db/models/manager.py", line 87, in manager_method
    return getattr(self.get_queryset(), name)(*args, **kwargs)
           ^^^^^^^^^^^^^^^^^^^^^^^^^^^^^^^^^^^^^^^^^^^^^^^^^^^
  File "/usr/local/lib/python3.11/site-packages/django/db/models/query.py", line 1864, in _insert
    return query.get_compiler(using=using).execute_sql(returning_fields)
           ^^^^^^^^^^^^^^^^^^^^^^^^^^^^^^^^^^^^^^^^^^^^^^^^^^^^^^^^^^^^^
  File "/usr/local/lib/python3.11/site-packages/django/db/models/sql/compiler.py", line 1882, in execute_sql
    cursor.execute(sql, params)
  File "/usr/local/lib/python3.11/site-packages/django/db/backends/utils.py", line 122, in execute
    return super().execute(sql, params)
           ^^^^^^^^^^^^^^^^^^^^^^^^^^^^
  File "/usr/local/lib/python3.11/site-packages/django/db/backends/utils.py", line 79, in execute
    return self._execute_with_wrappers(
           ^^^^^^^^^^^^^^^^^^^^^^^^^^^^
  File "/usr/local/lib/python3.11/site-packages/django/db/backends/utils.py", line 92, in _execute_with_wrappers
    return executor(sql, params, many, context)
           ^^^^^^^^^^^^^^^^^^^^^^^^^^^^^^^^^^^^
  File "/usr/local/lib/python3.11/site-packages/django/db/backends/utils.py", line 100, in _execute
    with self.db.wrap_database_errors:
  File "/usr/local/lib/python3.11/site-packages/django/db/utils.py", line 91, in __exit__
    raise dj_exc_value.with_traceback(traceback) from exc_value
  File "/usr/local/lib/python3.11/site-packages/django/db/backends/utils.py", line 105, in _execute
    return self.cursor.execute(sql, params)
           ^^^^^^^^^^^^^^^^^^^^^^^^^^^^^^^^
django.db.utils.IntegrityError: duplicate key value violates unique constraint "authentication_userprofile_user_id_key"
DETAIL:  Key (user_id)=(2df45b91-5448-41a2-950e-2ac598127d3f) already exists.

ERROR 2025-06-04 04:20:35,384 basehttp 11 140307643492032 "POST /api/auth/register/ HTTP/1.0" 500 190047
ERROR 2025-06-04 04:25:59,680 log 11 140307643492032 Internal Server Error: /api/auth/register/
Traceback (most recent call last):
  File "/usr/local/lib/python3.11/site-packages/django/db/backends/utils.py", line 105, in _execute
    return self.cursor.execute(sql, params)
           ^^^^^^^^^^^^^^^^^^^^^^^^^^^^^^^^
psycopg2.errors.UniqueViolation: duplicate key value violates unique constraint "authentication_userprofile_user_id_key"
DETAIL:  Key (user_id)=(eaa23e3c-57d0-4601-a471-1a81847d56ee) already exists.


The above exception was the direct cause of the following exception:

Traceback (most recent call last):
  File "/usr/local/lib/python3.11/site-packages/django/core/handlers/exception.py", line 55, in inner
    response = get_response(request)
               ^^^^^^^^^^^^^^^^^^^^^
  File "/usr/local/lib/python3.11/site-packages/django/core/handlers/base.py", line 197, in _get_response
    response = wrapped_callback(request, *callback_args, **callback_kwargs)
               ^^^^^^^^^^^^^^^^^^^^^^^^^^^^^^^^^^^^^^^^^^^^^^^^^^^^^^^^^^^^
  File "/usr/local/lib/python3.11/site-packages/django/views/decorators/csrf.py", line 65, in _view_wrapper
    return view_func(request, *args, **kwargs)
           ^^^^^^^^^^^^^^^^^^^^^^^^^^^^^^^^^^^
  File "/usr/local/lib/python3.11/site-packages/django/views/generic/base.py", line 104, in view
    return self.dispatch(request, *args, **kwargs)
           ^^^^^^^^^^^^^^^^^^^^^^^^^^^^^^^^^^^^^^^
  File "/usr/local/lib/python3.11/site-packages/rest_framework/views.py", line 509, in dispatch
    response = self.handle_exception(exc)
               ^^^^^^^^^^^^^^^^^^^^^^^^^^
  File "/usr/local/lib/python3.11/site-packages/rest_framework/views.py", line 469, in handle_exception
    self.raise_uncaught_exception(exc)
  File "/usr/local/lib/python3.11/site-packages/rest_framework/views.py", line 480, in raise_uncaught_exception
    raise exc
  File "/usr/local/lib/python3.11/site-packages/rest_framework/views.py", line 506, in dispatch
    response = handler(request, *args, **kwargs)
               ^^^^^^^^^^^^^^^^^^^^^^^^^^^^^^^^^
  File "/usr/local/lib/python3.11/site-packages/rest_framework/decorators.py", line 50, in handler
    return func(*args, **kwargs)
           ^^^^^^^^^^^^^^^^^^^^^
  File "/app/authentication/views.py", line 56, in register
    user = serializer.save()
           ^^^^^^^^^^^^^^^^^
  File "/usr/local/lib/python3.11/site-packages/rest_framework/serializers.py", line 208, in save
    self.instance = self.create(validated_data)
                    ^^^^^^^^^^^^^^^^^^^^^^^^^^^
  File "/app/authentication/serializers.py", line 51, in create
    UserProfile.objects.create(user=user)
  File "/usr/local/lib/python3.11/site-packages/django/db/models/manager.py", line 87, in manager_method
    return getattr(self.get_queryset(), name)(*args, **kwargs)
           ^^^^^^^^^^^^^^^^^^^^^^^^^^^^^^^^^^^^^^^^^^^^^^^^^^^
  File "/usr/local/lib/python3.11/site-packages/django/db/models/query.py", line 663, in create
    obj.save(force_insert=True, using=self.db)
  File "/usr/local/lib/python3.11/site-packages/django/db/models/base.py", line 902, in save
    self.save_base(
  File "/usr/local/lib/python3.11/site-packages/django/db/models/base.py", line 1008, in save_base
    updated = self._save_table(
              ^^^^^^^^^^^^^^^^^
  File "/usr/local/lib/python3.11/site-packages/django/db/models/base.py", line 1169, in _save_table
    results = self._do_insert(
              ^^^^^^^^^^^^^^^^
  File "/usr/local/lib/python3.11/site-packages/django/db/models/base.py", line 1210, in _do_insert
    return manager._insert(
           ^^^^^^^^^^^^^^^^
  File "/usr/local/lib/python3.11/site-packages/django/db/models/manager.py", line 87, in manager_method
    return getattr(self.get_queryset(), name)(*args, **kwargs)
           ^^^^^^^^^^^^^^^^^^^^^^^^^^^^^^^^^^^^^^^^^^^^^^^^^^^
  File "/usr/local/lib/python3.11/site-packages/django/db/models/query.py", line 1864, in _insert
    return query.get_compiler(using=using).execute_sql(returning_fields)
           ^^^^^^^^^^^^^^^^^^^^^^^^^^^^^^^^^^^^^^^^^^^^^^^^^^^^^^^^^^^^^
  File "/usr/local/lib/python3.11/site-packages/django/db/models/sql/compiler.py", line 1882, in execute_sql
    cursor.execute(sql, params)
  File "/usr/local/lib/python3.11/site-packages/django/db/backends/utils.py", line 122, in execute
    return super().execute(sql, params)
           ^^^^^^^^^^^^^^^^^^^^^^^^^^^^
  File "/usr/local/lib/python3.11/site-packages/django/db/backends/utils.py", line 79, in execute
    return self._execute_with_wrappers(
           ^^^^^^^^^^^^^^^^^^^^^^^^^^^^
  File "/usr/local/lib/python3.11/site-packages/django/db/backends/utils.py", line 92, in _execute_with_wrappers
    return executor(sql, params, many, context)
           ^^^^^^^^^^^^^^^^^^^^^^^^^^^^^^^^^^^^
  File "/usr/local/lib/python3.11/site-packages/django/db/backends/utils.py", line 100, in _execute
    with self.db.wrap_database_errors:
  File "/usr/local/lib/python3.11/site-packages/django/db/utils.py", line 91, in __exit__
    raise dj_exc_value.with_traceback(traceback) from exc_value
  File "/usr/local/lib/python3.11/site-packages/django/db/backends/utils.py", line 105, in _execute
    return self.cursor.execute(sql, params)
           ^^^^^^^^^^^^^^^^^^^^^^^^^^^^^^^^
django.db.utils.IntegrityError: duplicate key value violates unique constraint "authentication_userprofile_user_id_key"
DETAIL:  Key (user_id)=(eaa23e3c-57d0-4601-a471-1a81847d56ee) already exists.

ERROR 2025-06-04 04:25:59,682 basehttp 11 140307643492032 "POST /api/auth/register/ HTTP/1.0" 500 190047
ERROR 2025-06-04 04:28:16,759 log 11 140307643492032 Internal Server Error: /api/auth/register/
Traceback (most recent call last):
  File "/usr/local/lib/python3.11/site-packages/django/db/backends/utils.py", line 105, in _execute
    return self.cursor.execute(sql, params)
           ^^^^^^^^^^^^^^^^^^^^^^^^^^^^^^^^
psycopg2.errors.UniqueViolation: duplicate key value violates unique constraint "authentication_userprofile_user_id_key"
DETAIL:  Key (user_id)=(50dcee5e-7ae3-4f34-9a19-3501216867e0) already exists.


The above exception was the direct cause of the following exception:

Traceback (most recent call last):
  File "/usr/local/lib/python3.11/site-packages/django/core/handlers/exception.py", line 55, in inner
    response = get_response(request)
               ^^^^^^^^^^^^^^^^^^^^^
  File "/usr/local/lib/python3.11/site-packages/django/core/handlers/base.py", line 197, in _get_response
    response = wrapped_callback(request, *callback_args, **callback_kwargs)
               ^^^^^^^^^^^^^^^^^^^^^^^^^^^^^^^^^^^^^^^^^^^^^^^^^^^^^^^^^^^^
  File "/usr/local/lib/python3.11/site-packages/django/views/decorators/csrf.py", line 65, in _view_wrapper
    return view_func(request, *args, **kwargs)
           ^^^^^^^^^^^^^^^^^^^^^^^^^^^^^^^^^^^
  File "/usr/local/lib/python3.11/site-packages/django/views/generic/base.py", line 104, in view
    return self.dispatch(request, *args, **kwargs)
           ^^^^^^^^^^^^^^^^^^^^^^^^^^^^^^^^^^^^^^^
  File "/usr/local/lib/python3.11/site-packages/rest_framework/views.py", line 509, in dispatch
    response = self.handle_exception(exc)
               ^^^^^^^^^^^^^^^^^^^^^^^^^^
  File "/usr/local/lib/python3.11/site-packages/rest_framework/views.py", line 469, in handle_exception
    self.raise_uncaught_exception(exc)
  File "/usr/local/lib/python3.11/site-packages/rest_framework/views.py", line 480, in raise_uncaught_exception
    raise exc
  File "/usr/local/lib/python3.11/site-packages/rest_framework/views.py", line 506, in dispatch
    response = handler(request, *args, **kwargs)
               ^^^^^^^^^^^^^^^^^^^^^^^^^^^^^^^^^
  File "/usr/local/lib/python3.11/site-packages/rest_framework/decorators.py", line 50, in handler
    return func(*args, **kwargs)
           ^^^^^^^^^^^^^^^^^^^^^
  File "/app/authentication/views.py", line 56, in register
    user = serializer.save()
           ^^^^^^^^^^^^^^^^^
  File "/usr/local/lib/python3.11/site-packages/rest_framework/serializers.py", line 208, in save
    self.instance = self.create(validated_data)
                    ^^^^^^^^^^^^^^^^^^^^^^^^^^^
  File "/app/authentication/serializers.py", line 51, in create
    UserProfile.objects.create(user=user)
  File "/usr/local/lib/python3.11/site-packages/django/db/models/manager.py", line 87, in manager_method
    return getattr(self.get_queryset(), name)(*args, **kwargs)
           ^^^^^^^^^^^^^^^^^^^^^^^^^^^^^^^^^^^^^^^^^^^^^^^^^^^
  File "/usr/local/lib/python3.11/site-packages/django/db/models/query.py", line 663, in create
    obj.save(force_insert=True, using=self.db)
  File "/usr/local/lib/python3.11/site-packages/django/db/models/base.py", line 902, in save
    self.save_base(
  File "/usr/local/lib/python3.11/site-packages/django/db/models/base.py", line 1008, in save_base
    updated = self._save_table(
              ^^^^^^^^^^^^^^^^^
  File "/usr/local/lib/python3.11/site-packages/django/db/models/base.py", line 1169, in _save_table
    results = self._do_insert(
              ^^^^^^^^^^^^^^^^
  File "/usr/local/lib/python3.11/site-packages/django/db/models/base.py", line 1210, in _do_insert
    return manager._insert(
           ^^^^^^^^^^^^^^^^
  File "/usr/local/lib/python3.11/site-packages/django/db/models/manager.py", line 87, in manager_method
    return getattr(self.get_queryset(), name)(*args, **kwargs)
           ^^^^^^^^^^^^^^^^^^^^^^^^^^^^^^^^^^^^^^^^^^^^^^^^^^^
  File "/usr/local/lib/python3.11/site-packages/django/db/models/query.py", line 1864, in _insert
    return query.get_compiler(using=using).execute_sql(returning_fields)
           ^^^^^^^^^^^^^^^^^^^^^^^^^^^^^^^^^^^^^^^^^^^^^^^^^^^^^^^^^^^^^
  File "/usr/local/lib/python3.11/site-packages/django/db/models/sql/compiler.py", line 1882, in execute_sql
    cursor.execute(sql, params)
  File "/usr/local/lib/python3.11/site-packages/django/db/backends/utils.py", line 122, in execute
    return super().execute(sql, params)
           ^^^^^^^^^^^^^^^^^^^^^^^^^^^^
  File "/usr/local/lib/python3.11/site-packages/django/db/backends/utils.py", line 79, in execute
    return self._execute_with_wrappers(
           ^^^^^^^^^^^^^^^^^^^^^^^^^^^^
  File "/usr/local/lib/python3.11/site-packages/django/db/backends/utils.py", line 92, in _execute_with_wrappers
    return executor(sql, params, many, context)
           ^^^^^^^^^^^^^^^^^^^^^^^^^^^^^^^^^^^^
  File "/usr/local/lib/python3.11/site-packages/django/db/backends/utils.py", line 100, in _execute
    with self.db.wrap_database_errors:
  File "/usr/local/lib/python3.11/site-packages/django/db/utils.py", line 91, in __exit__
    raise dj_exc_value.with_traceback(traceback) from exc_value
  File "/usr/local/lib/python3.11/site-packages/django/db/backends/utils.py", line 105, in _execute
    return self.cursor.execute(sql, params)
           ^^^^^^^^^^^^^^^^^^^^^^^^^^^^^^^^
django.db.utils.IntegrityError: duplicate key value violates unique constraint "authentication_userprofile_user_id_key"
DETAIL:  Key (user_id)=(50dcee5e-7ae3-4f34-9a19-3501216867e0) already exists.

ERROR 2025-06-04 04:28:16,762 basehttp 11 140307643492032 "POST /api/auth/register/ HTTP/1.0" 500 190071
INFO 2025-06-04 04:34:27,977 autoreload 11 140307725712256 /app/authentication/serializers.py changed, reloading.
INFO 2025-06-04 04:34:28,697 autoreload 34 140444306774912 Watching for file changes with StatReloader
INFO 2025-06-04 04:34:44,132 autoreload 34 140444306774912 /app/authentication/serializers.py changed, reloading.
INFO 2025-06-04 04:34:44,924 autoreload 36 140237036936064 Watching for file changes with StatReloader
INFO 2025-06-04 04:35:09,327 autoreload 11 140139789958016 Watching for file changes with StatReloader
ERROR 2025-06-04 04:35:17,139 log 11 140139707754176 Internal Server Error: /api/auth/register/
Traceback (most recent call last):
  File "/usr/local/lib/python3.11/site-packages/django/core/handlers/exception.py", line 55, in inner
    response = get_response(request)
               ^^^^^^^^^^^^^^^^^^^^^
  File "/usr/local/lib/python3.11/site-packages/django/core/handlers/base.py", line 197, in _get_response
    response = wrapped_callback(request, *callback_args, **callback_kwargs)
               ^^^^^^^^^^^^^^^^^^^^^^^^^^^^^^^^^^^^^^^^^^^^^^^^^^^^^^^^^^^^
  File "/usr/local/lib/python3.11/site-packages/django/views/decorators/csrf.py", line 65, in _view_wrapper
    return view_func(request, *args, **kwargs)
           ^^^^^^^^^^^^^^^^^^^^^^^^^^^^^^^^^^^
  File "/usr/local/lib/python3.11/site-packages/django/views/generic/base.py", line 104, in view
    return self.dispatch(request, *args, **kwargs)
           ^^^^^^^^^^^^^^^^^^^^^^^^^^^^^^^^^^^^^^^
  File "/usr/local/lib/python3.11/site-packages/rest_framework/views.py", line 509, in dispatch
    response = self.handle_exception(exc)
               ^^^^^^^^^^^^^^^^^^^^^^^^^^
  File "/usr/local/lib/python3.11/site-packages/rest_framework/views.py", line 469, in handle_exception
    self.raise_uncaught_exception(exc)
  File "/usr/local/lib/python3.11/site-packages/rest_framework/views.py", line 480, in raise_uncaught_exception
    raise exc
  File "/usr/local/lib/python3.11/site-packages/rest_framework/views.py", line 506, in dispatch
    response = handler(request, *args, **kwargs)
               ^^^^^^^^^^^^^^^^^^^^^^^^^^^^^^^^^
  File "/usr/local/lib/python3.11/site-packages/rest_framework/decorators.py", line 50, in handler
    return func(*args, **kwargs)
           ^^^^^^^^^^^^^^^^^^^^^
  File "/app/authentication/views.py", line 59, in register
    send_verification_email(user)
  File "/app/authentication/views.py", line 387, in send_verification_email
    send_mail(
  File "/usr/local/lib/python3.11/site-packages/django/core/mail/__init__.py", line 92, in send_mail
    return mail.send()
           ^^^^^^^^^^^
  File "/usr/local/lib/python3.11/site-packages/django/core/mail/message.py", line 307, in send
    return self.get_connection(fail_silently).send_messages([self])
           ^^^^^^^^^^^^^^^^^^^^^^^^^^^^^^^^^^^^^^^^^^^^^^^^^^^^^^^^
  File "/usr/local/lib/python3.11/site-packages/django/core/mail/backends/smtp.py", line 128, in send_messages
    new_conn_created = self.open()
                       ^^^^^^^^^^^
  File "/usr/local/lib/python3.11/site-packages/django/core/mail/backends/smtp.py", line 95, in open
    self.connection.login(self.username, self.password)
  File "/usr/local/lib/python3.11/smtplib.py", line 750, in login
    raise last_exception
  File "/usr/local/lib/python3.11/smtplib.py", line 739, in login
    (code, resp) = self.auth(
                   ^^^^^^^^^^
  File "/usr/local/lib/python3.11/smtplib.py", line 662, in auth
    raise SMTPAuthenticationError(code, resp)
smtplib.SMTPAuthenticationError: (535, b'5.7.8 Username and Password not accepted. For more information, go to\n5.7.8  https://support.google.com/mail/?p=BadCredentials d9443c01a7336-23506be23c1sm95313335ad.78 - gsmtp')
ERROR 2025-06-04 04:35:17,142 basehttp 11 140139707754176 "POST /api/auth/register/ HTTP/1.0" 500 133405
WARNING 2025-06-04 04:36:18,673 log 11 140139707754176 Bad Request: /api/auth/register/
WARNING 2025-06-04 04:36:18,674 basehttp 11 140139707754176 "POST /api/auth/register/ HTTP/1.0" 400 47
WARNING 2025-06-04 04:36:41,099 log 11 140139707754176 Bad Request: /api/auth/register/
WARNING 2025-06-04 04:36:41,099 basehttp 11 140139707754176 "POST /api/auth/register/ HTTP/1.0" 400 47
INFO 2025-06-04 04:39:23,449 autoreload 10 140003482160000 Watching for file changes with StatReloader
WARNING 2025-06-04 04:39:34,484 log 10 140003400214208 Bad Request: /api/auth/register/
WARNING 2025-06-04 04:39:34,484 basehttp 10 140003400214208 "POST /api/auth/register/ HTTP/1.0" 400 107
ERROR 2025-06-04 04:40:06,610 log 10 140003400214208 Internal Server Error: /api/auth/register/
Traceback (most recent call last):
  File "/usr/local/lib/python3.11/site-packages/django/core/handlers/exception.py", line 55, in inner
    response = get_response(request)
               ^^^^^^^^^^^^^^^^^^^^^
  File "/usr/local/lib/python3.11/site-packages/django/core/handlers/base.py", line 197, in _get_response
    response = wrapped_callback(request, *callback_args, **callback_kwargs)
               ^^^^^^^^^^^^^^^^^^^^^^^^^^^^^^^^^^^^^^^^^^^^^^^^^^^^^^^^^^^^
  File "/usr/local/lib/python3.11/site-packages/django/views/decorators/csrf.py", line 65, in _view_wrapper
    return view_func(request, *args, **kwargs)
           ^^^^^^^^^^^^^^^^^^^^^^^^^^^^^^^^^^^
  File "/usr/local/lib/python3.11/site-packages/django/views/generic/base.py", line 104, in view
    return self.dispatch(request, *args, **kwargs)
           ^^^^^^^^^^^^^^^^^^^^^^^^^^^^^^^^^^^^^^^
  File "/usr/local/lib/python3.11/site-packages/rest_framework/views.py", line 509, in dispatch
    response = self.handle_exception(exc)
               ^^^^^^^^^^^^^^^^^^^^^^^^^^
  File "/usr/local/lib/python3.11/site-packages/rest_framework/views.py", line 469, in handle_exception
    self.raise_uncaught_exception(exc)
  File "/usr/local/lib/python3.11/site-packages/rest_framework/views.py", line 480, in raise_uncaught_exception
    raise exc
  File "/usr/local/lib/python3.11/site-packages/rest_framework/views.py", line 506, in dispatch
    response = handler(request, *args, **kwargs)
               ^^^^^^^^^^^^^^^^^^^^^^^^^^^^^^^^^
  File "/usr/local/lib/python3.11/site-packages/rest_framework/decorators.py", line 50, in handler
    return func(*args, **kwargs)
           ^^^^^^^^^^^^^^^^^^^^^
  File "/app/authentication/views.py", line 59, in register
    send_verification_email(user)
  File "/app/authentication/views.py", line 387, in send_verification_email
    send_mail(
  File "/usr/local/lib/python3.11/site-packages/django/core/mail/__init__.py", line 92, in send_mail
    return mail.send()
           ^^^^^^^^^^^
  File "/usr/local/lib/python3.11/site-packages/django/core/mail/message.py", line 307, in send
    return self.get_connection(fail_silently).send_messages([self])
           ^^^^^^^^^^^^^^^^^^^^^^^^^^^^^^^^^^^^^^^^^^^^^^^^^^^^^^^^
  File "/usr/local/lib/python3.11/site-packages/django/core/mail/backends/smtp.py", line 128, in send_messages
    new_conn_created = self.open()
                       ^^^^^^^^^^^
  File "/usr/local/lib/python3.11/site-packages/django/core/mail/backends/smtp.py", line 95, in open
    self.connection.login(self.username, self.password)
  File "/usr/local/lib/python3.11/smtplib.py", line 750, in login
    raise last_exception
  File "/usr/local/lib/python3.11/smtplib.py", line 739, in login
    (code, resp) = self.auth(
                   ^^^^^^^^^^
  File "/usr/local/lib/python3.11/smtplib.py", line 662, in auth
    raise SMTPAuthenticationError(code, resp)
smtplib.SMTPAuthenticationError: (535, b'5.7.8 Username and Password not accepted. For more information, go to\n5.7.8  https://support.google.com/mail/?p=BadCredentials d9443c01a7336-23506cd36acsm95424935ad.144 - gsmtp')
ERROR 2025-06-04 04:40:06,613 basehttp 10 140003400214208 "POST /api/auth/register/ HTTP/1.0" 500 133398
INFO 2025-06-06 08:42:24,709 autoreload 11 140014102453120 Watching for file changes with StatReloader
INFO 2025-06-06 08:58:25,091 autoreload 11 140505043676032 Watching for file changes with StatReloader
INFO 2025-06-06 09:00:02,582 autoreload 11 139630752242560 Watching for file changes with StatReloader
INFO 2025-06-06 10:41:09,535 autoreload 11 140450233555840 Watching for file changes with StatReloader
INFO 2025-06-06 11:26:38,525 autoreload 11 140578602232704 Watching for file changes with StatReloader
INFO 2025-06-06 11:27:21,617 basehttp 11 140578520032960 "OPTIONS /api/auth/login/ HTTP/1.0" 200 0
WARNING 2025-06-06 11:27:21,939 log 11 140578520032960 Unauthorized: /api/auth/login/
WARNING 2025-06-06 11:27:21,939 basehttp 11 140578520032960 "POST /api/auth/login/ HTTP/1.0" 401 51
INFO 2025-06-06 11:27:49,397 basehttp 11 140578520032960 "OPTIONS /api/auth/register/ HTTP/1.0" 200 0
WARNING 2025-06-06 11:27:49,420 log 11 140578520032960 Bad Request: /api/auth/register/
WARNING 2025-06-06 11:27:49,420 basehttp 11 140578520032960 "POST /api/auth/register/ HTTP/1.0" 400 82
ERROR 2025-06-06 11:28:05,917 log 11 140578520032960 Internal Server Error: /api/auth/register/
Traceback (most recent call last):
  File "/usr/local/lib/python3.11/site-packages/django/core/handlers/exception.py", line 55, in inner
    response = get_response(request)
               ^^^^^^^^^^^^^^^^^^^^^
  File "/usr/local/lib/python3.11/site-packages/django/core/handlers/base.py", line 197, in _get_response
    response = wrapped_callback(request, *callback_args, **callback_kwargs)
               ^^^^^^^^^^^^^^^^^^^^^^^^^^^^^^^^^^^^^^^^^^^^^^^^^^^^^^^^^^^^
  File "/usr/local/lib/python3.11/site-packages/django/views/decorators/csrf.py", line 65, in _view_wrapper
    return view_func(request, *args, **kwargs)
           ^^^^^^^^^^^^^^^^^^^^^^^^^^^^^^^^^^^
  File "/usr/local/lib/python3.11/site-packages/django/views/generic/base.py", line 104, in view
    return self.dispatch(request, *args, **kwargs)
           ^^^^^^^^^^^^^^^^^^^^^^^^^^^^^^^^^^^^^^^
  File "/usr/local/lib/python3.11/site-packages/rest_framework/views.py", line 509, in dispatch
    response = self.handle_exception(exc)
               ^^^^^^^^^^^^^^^^^^^^^^^^^^
  File "/usr/local/lib/python3.11/site-packages/rest_framework/views.py", line 469, in handle_exception
    self.raise_uncaught_exception(exc)
  File "/usr/local/lib/python3.11/site-packages/rest_framework/views.py", line 480, in raise_uncaught_exception
    raise exc
  File "/usr/local/lib/python3.11/site-packages/rest_framework/views.py", line 506, in dispatch
    response = handler(request, *args, **kwargs)
               ^^^^^^^^^^^^^^^^^^^^^^^^^^^^^^^^^
  File "/usr/local/lib/python3.11/site-packages/rest_framework/decorators.py", line 50, in handler
    return func(*args, **kwargs)
           ^^^^^^^^^^^^^^^^^^^^^
  File "/app/authentication/views.py", line 59, in register
    send_verification_email(user)
  File "/app/authentication/views.py", line 387, in send_verification_email
    send_mail(
  File "/usr/local/lib/python3.11/site-packages/django/core/mail/__init__.py", line 92, in send_mail
    return mail.send()
           ^^^^^^^^^^^
  File "/usr/local/lib/python3.11/site-packages/django/core/mail/message.py", line 307, in send
    return self.get_connection(fail_silently).send_messages([self])
           ^^^^^^^^^^^^^^^^^^^^^^^^^^^^^^^^^^^^^^^^^^^^^^^^^^^^^^^^
  File "/usr/local/lib/python3.11/site-packages/django/core/mail/backends/smtp.py", line 128, in send_messages
    new_conn_created = self.open()
                       ^^^^^^^^^^^
  File "/usr/local/lib/python3.11/site-packages/django/core/mail/backends/smtp.py", line 95, in open
    self.connection.login(self.username, self.password)
  File "/usr/local/lib/python3.11/smtplib.py", line 750, in login
    raise last_exception
  File "/usr/local/lib/python3.11/smtplib.py", line 739, in login
    (code, resp) = self.auth(
                   ^^^^^^^^^^
  File "/usr/local/lib/python3.11/smtplib.py", line 662, in auth
    raise SMTPAuthenticationError(code, resp)
smtplib.SMTPAuthenticationError: (535, b'5.7.8 Username and Password not accepted. For more information, go to\n5.7.8  https://support.google.com/mail/?p=BadCredentials 98e67ed59e1d1-3134b09067dsm1043030a91.22 - gsmtp')
ERROR 2025-06-06 11:28:05,921 basehttp 11 140578520032960 "POST /api/auth/register/ HTTP/1.0" 500 135209
INFO 2025-06-06 11:43:28,119 autoreload 11 139990790351744 Watching for file changes with StatReloader
WARNING 2025-06-06 11:44:21,771 log 11 139990633805504 Bad Request: /api/auth/register/
WARNING 2025-06-06 11:44:21,772 basehttp 11 139990633805504 "POST /api/auth/register/ HTTP/1.0" 400 47
ERROR 2025-06-06 11:44:38,063 log 11 139990633805504 Internal Server Error: /api/auth/register/
Traceback (most recent call last):
  File "/usr/local/lib/python3.11/site-packages/django/core/handlers/exception.py", line 55, in inner
    response = get_response(request)
               ^^^^^^^^^^^^^^^^^^^^^
  File "/usr/local/lib/python3.11/site-packages/django/core/handlers/base.py", line 197, in _get_response
    response = wrapped_callback(request, *callback_args, **callback_kwargs)
               ^^^^^^^^^^^^^^^^^^^^^^^^^^^^^^^^^^^^^^^^^^^^^^^^^^^^^^^^^^^^
  File "/usr/local/lib/python3.11/site-packages/django/views/decorators/csrf.py", line 65, in _view_wrapper
    return view_func(request, *args, **kwargs)
           ^^^^^^^^^^^^^^^^^^^^^^^^^^^^^^^^^^^
  File "/usr/local/lib/python3.11/site-packages/django/views/generic/base.py", line 104, in view
    return self.dispatch(request, *args, **kwargs)
           ^^^^^^^^^^^^^^^^^^^^^^^^^^^^^^^^^^^^^^^
  File "/usr/local/lib/python3.11/site-packages/rest_framework/views.py", line 509, in dispatch
    response = self.handle_exception(exc)
               ^^^^^^^^^^^^^^^^^^^^^^^^^^
  File "/usr/local/lib/python3.11/site-packages/rest_framework/views.py", line 469, in handle_exception
    self.raise_uncaught_exception(exc)
  File "/usr/local/lib/python3.11/site-packages/rest_framework/views.py", line 480, in raise_uncaught_exception
    raise exc
  File "/usr/local/lib/python3.11/site-packages/rest_framework/views.py", line 506, in dispatch
    response = handler(request, *args, **kwargs)
               ^^^^^^^^^^^^^^^^^^^^^^^^^^^^^^^^^
  File "/usr/local/lib/python3.11/site-packages/rest_framework/decorators.py", line 50, in handler
    return func(*args, **kwargs)
           ^^^^^^^^^^^^^^^^^^^^^
  File "/app/authentication/views.py", line 59, in register
    send_verification_email(user)
  File "/app/authentication/views.py", line 387, in send_verification_email
    send_mail(
  File "/usr/local/lib/python3.11/site-packages/django/core/mail/__init__.py", line 92, in send_mail
    return mail.send()
           ^^^^^^^^^^^
  File "/usr/local/lib/python3.11/site-packages/django/core/mail/message.py", line 307, in send
    return self.get_connection(fail_silently).send_messages([self])
           ^^^^^^^^^^^^^^^^^^^^^^^^^^^^^^^^^^^^^^^^^^^^^^^^^^^^^^^^
  File "/usr/local/lib/python3.11/site-packages/django/core/mail/backends/smtp.py", line 128, in send_messages
    new_conn_created = self.open()
                       ^^^^^^^^^^^
  File "/usr/local/lib/python3.11/site-packages/django/core/mail/backends/smtp.py", line 95, in open
    self.connection.login(self.username, self.password)
  File "/usr/local/lib/python3.11/smtplib.py", line 750, in login
    raise last_exception
  File "/usr/local/lib/python3.11/smtplib.py", line 739, in login
    (code, resp) = self.auth(
                   ^^^^^^^^^^
  File "/usr/local/lib/python3.11/smtplib.py", line 662, in auth
    raise SMTPAuthenticationError(code, resp)
smtplib.SMTPAuthenticationError: (535, b'5.7.8 Username and Password not accepted. For more information, go to\n5.7.8  https://support.google.com/mail/?p=BadCredentials 98e67ed59e1d1-31349fc5361sm1148557a91.24 - gsmtp')
ERROR 2025-06-06 11:44:38,068 basehttp 11 139990633805504 "POST /api/auth/register/ HTTP/1.0" 500 135229
ERROR 2025-06-06 11:45:47,326 log 11 139990633805504 Internal Server Error: /api/auth/register/
Traceback (most recent call last):
  File "/usr/local/lib/python3.11/site-packages/django/core/handlers/exception.py", line 55, in inner
    response = get_response(request)
               ^^^^^^^^^^^^^^^^^^^^^
  File "/usr/local/lib/python3.11/site-packages/django/core/handlers/base.py", line 197, in _get_response
    response = wrapped_callback(request, *callback_args, **callback_kwargs)
               ^^^^^^^^^^^^^^^^^^^^^^^^^^^^^^^^^^^^^^^^^^^^^^^^^^^^^^^^^^^^
  File "/usr/local/lib/python3.11/site-packages/django/views/decorators/csrf.py", line 65, in _view_wrapper
    return view_func(request, *args, **kwargs)
           ^^^^^^^^^^^^^^^^^^^^^^^^^^^^^^^^^^^
  File "/usr/local/lib/python3.11/site-packages/django/views/generic/base.py", line 104, in view
    return self.dispatch(request, *args, **kwargs)
           ^^^^^^^^^^^^^^^^^^^^^^^^^^^^^^^^^^^^^^^
  File "/usr/local/lib/python3.11/site-packages/rest_framework/views.py", line 509, in dispatch
    response = self.handle_exception(exc)
               ^^^^^^^^^^^^^^^^^^^^^^^^^^
  File "/usr/local/lib/python3.11/site-packages/rest_framework/views.py", line 469, in handle_exception
    self.raise_uncaught_exception(exc)
  File "/usr/local/lib/python3.11/site-packages/rest_framework/views.py", line 480, in raise_uncaught_exception
    raise exc
  File "/usr/local/lib/python3.11/site-packages/rest_framework/views.py", line 506, in dispatch
    response = handler(request, *args, **kwargs)
               ^^^^^^^^^^^^^^^^^^^^^^^^^^^^^^^^^
  File "/usr/local/lib/python3.11/site-packages/rest_framework/decorators.py", line 50, in handler
    return func(*args, **kwargs)
           ^^^^^^^^^^^^^^^^^^^^^
  File "/app/authentication/views.py", line 59, in register
    send_verification_email(user)
  File "/app/authentication/views.py", line 387, in send_verification_email
    send_mail(
  File "/usr/local/lib/python3.11/site-packages/django/core/mail/__init__.py", line 92, in send_mail
    return mail.send()
           ^^^^^^^^^^^
  File "/usr/local/lib/python3.11/site-packages/django/core/mail/message.py", line 307, in send
    return self.get_connection(fail_silently).send_messages([self])
           ^^^^^^^^^^^^^^^^^^^^^^^^^^^^^^^^^^^^^^^^^^^^^^^^^^^^^^^^
  File "/usr/local/lib/python3.11/site-packages/django/core/mail/backends/smtp.py", line 128, in send_messages
    new_conn_created = self.open()
                       ^^^^^^^^^^^
  File "/usr/local/lib/python3.11/site-packages/django/core/mail/backends/smtp.py", line 95, in open
    self.connection.login(self.username, self.password)
  File "/usr/local/lib/python3.11/smtplib.py", line 750, in login
    raise last_exception
  File "/usr/local/lib/python3.11/smtplib.py", line 739, in login
    (code, resp) = self.auth(
                   ^^^^^^^^^^
  File "/usr/local/lib/python3.11/smtplib.py", line 662, in auth
    raise SMTPAuthenticationError(code, resp)
smtplib.SMTPAuthenticationError: (535, b'5.7.8 Username and Password not accepted. For more information, go to\n5.7.8  https://support.google.com/mail/?p=BadCredentials 98e67ed59e1d1-31349f32ea9sm1162079a91.14 - gsmtp')
ERROR 2025-06-06 11:45:47,328 basehttp 11 139990633805504 "POST /api/auth/register/ HTTP/1.0" 500 135229
INFO 2025-06-06 11:51:40,076 autoreload 11 139990790351744 /app/config/settings.py changed, reloading.
INFO 2025-06-06 11:51:40,776 autoreload 16 139898047576960 Watching for file changes with StatReloader
INFO 2025-06-06 11:52:36,812 basehttp 16 139897965897408 "POST /api/auth/register/ HTTP/1.0" 201 632
INFO 2025-06-06 11:53:08,115 basehttp 16 139897965897408 "POST /api/auth/login/ HTTP/1.0" 200 601
INFO 2025-06-06 11:53:09,302 basehttp 16 139897965897408 "OPTIONS /api/auth/profile/ HTTP/1.0" 200 0
INFO 2025-06-06 11:53:09,316 basehttp 16 139897965897408 "GET /api/auth/profile/ HTTP/1.0" 200 512
INFO 2025-06-06 11:53:19,846 basehttp 16 139897965897408 "GET /api/auth/profile/ HTTP/1.0" 200 512
INFO 2025-06-06 11:53:20,132 basehttp 16 139897965897408 "GET /api/auth/profile/ HTTP/1.0" 200 512
INFO 2025-06-06 11:53:20,898 basehttp 16 139897965897408 "GET /api/auth/profile/ HTTP/1.0" 200 512
INFO 2025-06-06 11:53:23,679 basehttp 16 139897965897408 "GET /api/auth/profile/ HTTP/1.0" 200 512
INFO 2025-06-06 11:53:29,223 basehttp 16 139897965897408 "GET /api/auth/profile/ HTTP/1.0" 200 512
INFO 2025-06-06 11:53:29,622 basehttp 16 139897965897408 "GET /api/auth/profile/ HTTP/1.0" 200 512
